ERROR:root:API error: 403 - {"message":"You are not subscribed to this API."}
ERROR:root:API error: 403 - {"message":"You are not subscribed to this API."}
ERROR:root:API error: 429 - {"message":"Too many requests"}
ERROR:root:API error: 403 - {"message":"You are not subscribed to this API."}
ERROR:root:API error: 429 - {"message":"Too many requests"}
ERROR:root:API error: 403 - {"message":"You are not subscribed to this API."}
ERROR:root:API error: 404 - {"message":"Endpoint '\/vin' does not exist"}
ERROR:root:API error: 404 - {"message":"Endpoint '\/vin' does not exist"}
ERROR:root:API error: 404 - {"message":"Endpoint '\/vin' does not exist"}
ERROR:root:API error: 404 - {"message":"Endpoint '\/vin' does not exist"}
ERROR:root:API error: 404 - {"message":"Endpoint '\/vin' does not exist"}
ERROR:root:Exception during VIN lookup: HTTPSConnectionPool(host='api.api-ninjas.com', port=443): Max retries exceeded with url: /v1/vinlookup?vin=JH4KA7561PC008269 (Caused by NameResolutionError("<urllib3.connection.HTTPSConnection object at 0x0000020FA3F4D290>: Failed to resolve 'api.api-ninjas.com' ([Errno 11001] getaddrinfo failed)"))
ERROR:root:Cars API error: 400 - {"error": "Missing API Key."}
ERROR:root:Cars API error: 400 - {"error": "Missing API Key."}
ERROR:root:Cars API error: 400 - {"error": "Missing API Key."}
ERROR:root:Cars API error: 400 - {"error": "Missing API Key."}
ERROR:root:API error: 400 - {"error": "Missing API Key."}
ERROR:nicegui:name 'app' is not defined
  + Exception Group Traceback (most recent call last):
  |   File "C:\Users\Keila\AppData\Local\Programs\Python\Python311\Lib\site-packages\starlette\_utils.py", line 76, in collapse_excgroups
  |     yield
  |   File "C:\Users\Keila\AppData\Local\Programs\Python\Python311\Lib\site-packages\starlette\middleware\base.py", line 178, in __call__
  |     async with anyio.create_task_group() as task_group:
  |   File "C:\Users\Keila\AppData\Local\Programs\Python\Python311\Lib\site-packages\anyio\_backends\_asyncio.py", line 767, in __aexit__
  |     raise BaseExceptionGroup(
  | ExceptionGroup: unhandled errors in a TaskGroup (1 sub-exception)
  +-+---------------- 1 ----------------
    | Traceback (most recent call last):
    |   File "C:\Users\Keila\AppData\Local\Programs\Python\Python311\Lib\site-packages\starlette\middleware\errors.py", line 165, in __call__
    |     await self.app(scope, receive, _send)
    |   File "C:\Users\Keila\AppData\Local\Programs\Python\Python311\Lib\site-packages\starlette\middleware\base.py", line 177, in __call__
    |     with recv_stream, send_stream, collapse_excgroups():
    |   File "C:\Users\Keila\AppData\Local\Programs\Python\Python311\Lib\contextlib.py", line 155, in __exit__
    |     self.gen.throw(typ, value, traceback)
    |   File "C:\Users\Keila\AppData\Local\Programs\Python\Python311\Lib\site-packages\starlette\_utils.py", line 82, in collapse_excgroups
    |     raise exc
    |   File "C:\Users\Keila\AppData\Local\Programs\Python\Python311\Lib\site-packages\starlette\middleware\base.py", line 179, in __call__
    |     response = await self.dispatch_func(request, call_next)
    |                ^^^^^^^^^^^^^^^^^^^^^^^^^^^^^^^^^^^^^^^^^^^^
    |   File "C:\Users\Keila\AppData\Local\Programs\Python\Python311\Lib\site-packages\nicegui\middlewares.py", line 23, in dispatch
    |     response = await call_next(request)
    |                ^^^^^^^^^^^^^^^^^^^^^^^^
    |   File "C:\Users\Keila\AppData\Local\Programs\Python\Python311\Lib\site-packages\starlette\middleware\base.py", line 154, in call_next
    |     raise app_exc
    |   File "C:\Users\Keila\AppData\Local\Programs\Python\Python311\Lib\site-packages\starlette\middleware\base.py", line 141, in coro
    |     await self.app(scope, receive_or_disconnect, send_no_error)
    |   File "C:\Users\Keila\AppData\Local\Programs\Python\Python311\Lib\site-packages\starlette\middleware\base.py", line 177, in __call__
    |     with recv_stream, send_stream, collapse_excgroups():
    |   File "C:\Users\Keila\AppData\Local\Programs\Python\Python311\Lib\contextlib.py", line 155, in __exit__
    |     self.gen.throw(typ, value, traceback)
    |   File "C:\Users\Keila\AppData\Local\Programs\Python\Python311\Lib\site-packages\starlette\_utils.py", line 82, in collapse_excgroups
    |     raise exc
    |   File "C:\Users\Keila\AppData\Local\Programs\Python\Python311\Lib\site-packages\starlette\middleware\base.py", line 179, in __call__
    |     response = await self.dispatch_func(request, call_next)
    |                ^^^^^^^^^^^^^^^^^^^^^^^^^^^^^^^^^^^^^^^^^^^^
    |   File "C:\Users\Keila\AppData\Local\Programs\Python\Python311\Lib\site-packages\nicegui\middlewares.py", line 13, in dispatch
    |     response = await call_next(request)
    |                ^^^^^^^^^^^^^^^^^^^^^^^^
    |   File "C:\Users\Keila\AppData\Local\Programs\Python\Python311\Lib\site-packages\starlette\middleware\base.py", line 154, in call_next
    |     raise app_exc
    |   File "C:\Users\Keila\AppData\Local\Programs\Python\Python311\Lib\site-packages\starlette\middleware\base.py", line 141, in coro
    |     await self.app(scope, receive_or_disconnect, send_no_error)
    |   File "C:\Users\Keila\AppData\Local\Programs\Python\Python311\Lib\site-packages\starlette\middleware\gzip.py", line 20, in __call__
    |     await responder(scope, receive, send)
    |   File "C:\Users\Keila\AppData\Local\Programs\Python\Python311\Lib\site-packages\starlette\middleware\gzip.py", line 39, in __call__
    |     await self.app(scope, receive, self.send_with_gzip)
    |   File "C:\Users\Keila\AppData\Local\Programs\Python\Python311\Lib\site-packages\starlette\middleware\exceptions.py", line 62, in __call__
    |     await wrap_app_handling_exceptions(self.app, conn)(scope, receive, send)
    |   File "C:\Users\Keila\AppData\Local\Programs\Python\Python311\Lib\site-packages\starlette\_exception_handler.py", line 53, in wrapped_app
    |     raise exc
    |   File "C:\Users\Keila\AppData\Local\Programs\Python\Python311\Lib\site-packages\starlette\_exception_handler.py", line 42, in wrapped_app
    |     await app(scope, receive, sender)
    |   File "C:\Users\Keila\AppData\Local\Programs\Python\Python311\Lib\site-packages\starlette\routing.py", line 715, in __call__
    |     await self.middleware_stack(scope, receive, send)
    |   File "C:\Users\Keila\AppData\Local\Programs\Python\Python311\Lib\site-packages\starlette\routing.py", line 735, in app
    |     await route.handle(scope, receive, send)
    |   File "C:\Users\Keila\AppData\Local\Programs\Python\Python311\Lib\site-packages\starlette\routing.py", line 288, in handle
    |     await self.app(scope, receive, send)
    |   File "C:\Users\Keila\AppData\Local\Programs\Python\Python311\Lib\site-packages\starlette\routing.py", line 76, in app
    |     await wrap_app_handling_exceptions(app, request)(scope, receive, send)
    |   File "C:\Users\Keila\AppData\Local\Programs\Python\Python311\Lib\site-packages\starlette\_exception_handler.py", line 53, in wrapped_app
    |     raise exc
    |   File "C:\Users\Keila\AppData\Local\Programs\Python\Python311\Lib\site-packages\starlette\_exception_handler.py", line 42, in wrapped_app
    |     await app(scope, receive, sender)
    |   File "C:\Users\Keila\AppData\Local\Programs\Python\Python311\Lib\site-packages\starlette\routing.py", line 73, in app
    |     response = await f(request)
    |                ^^^^^^^^^^^^^^^^
    |   File "C:\Users\Keila\AppData\Local\Programs\Python\Python311\Lib\site-packages\fastapi\routing.py", line 301, in app
    |     raw_response = await run_endpoint_function(
    |                    ^^^^^^^^^^^^^^^^^^^^^^^^^^^^
    |   File "C:\Users\Keila\AppData\Local\Programs\Python\Python311\Lib\site-packages\fastapi\routing.py", line 212, in run_endpoint_function
    |     return await dependant.call(**values)
    |            ^^^^^^^^^^^^^^^^^^^^^^^^^^^^^^
    |   File "C:\Users\Keila\AppData\Local\Programs\Python\Python311\Lib\site-packages\nicegui\page.py", line 153, in decorated
    |     return create_error_page(e, request)
    |            ^^^^^^^^^^^^^^^^^^^^^^^^^^^^^
    |   File "C:\Users\Keila\AppData\Local\Programs\Python\Python311\Lib\site-packages\nicegui\page.py", line 116, in create_error_page
    |     raise e
    |   File "C:\Users\Keila\AppData\Local\Programs\Python\Python311\Lib\site-packages\nicegui\page.py", line 147, in decorated
    |     result = func(*dec_args, **dec_kwargs)
    |              ^^^^^^^^^^^^^^^^^^^^^^^^^^^^^
    |   File "c:\Users\Keila\Downloads\VehicleMax-main (1)\VehicleMax-main\VIN_Decoder\VIN-Decoder.py", line 29, in vin_decoder_page
    |     for url in app.urls:
    |                ^^^
    | NameError: name 'app' is not defined
    +------------------------------------

During handling of the above exception, another exception occurred:

Traceback (most recent call last):
  File "C:\Users\Keila\AppData\Local\Programs\Python\Python311\Lib\site-packages\starlette\middleware\errors.py", line 165, in __call__
    await self.app(scope, receive, _send)
  File "C:\Users\Keila\AppData\Local\Programs\Python\Python311\Lib\site-packages\starlette\middleware\base.py", line 177, in __call__
    with recv_stream, send_stream, collapse_excgroups():
  File "C:\Users\Keila\AppData\Local\Programs\Python\Python311\Lib\contextlib.py", line 155, in __exit__
    self.gen.throw(typ, value, traceback)
  File "C:\Users\Keila\AppData\Local\Programs\Python\Python311\Lib\site-packages\starlette\_utils.py", line 82, in collapse_excgroups
    raise exc
  File "C:\Users\Keila\AppData\Local\Programs\Python\Python311\Lib\site-packages\starlette\middleware\base.py", line 179, in __call__
    response = await self.dispatch_func(request, call_next)
               ^^^^^^^^^^^^^^^^^^^^^^^^^^^^^^^^^^^^^^^^^^^^
  File "C:\Users\Keila\AppData\Local\Programs\Python\Python311\Lib\site-packages\nicegui\middlewares.py", line 23, in dispatch
    response = await call_next(request)
               ^^^^^^^^^^^^^^^^^^^^^^^^
  File "C:\Users\Keila\AppData\Local\Programs\Python\Python311\Lib\site-packages\starlette\middleware\base.py", line 154, in call_next
    raise app_exc
  File "C:\Users\Keila\AppData\Local\Programs\Python\Python311\Lib\site-packages\starlette\middleware\base.py", line 141, in coro
    await self.app(scope, receive_or_disconnect, send_no_error)
  File "C:\Users\Keila\AppData\Local\Programs\Python\Python311\Lib\site-packages\starlette\middleware\base.py", line 177, in __call__
    with recv_stream, send_stream, collapse_excgroups():
  File "C:\Users\Keila\AppData\Local\Programs\Python\Python311\Lib\contextlib.py", line 155, in __exit__
    self.gen.throw(typ, value, traceback)
  File "C:\Users\Keila\AppData\Local\Programs\Python\Python311\Lib\site-packages\starlette\_utils.py", line 82, in collapse_excgroups
    raise exc
  File "C:\Users\Keila\AppData\Local\Programs\Python\Python311\Lib\site-packages\starlette\middleware\base.py", line 179, in __call__
    response = await self.dispatch_func(request, call_next)
               ^^^^^^^^^^^^^^^^^^^^^^^^^^^^^^^^^^^^^^^^^^^^
  File "C:\Users\Keila\AppData\Local\Programs\Python\Python311\Lib\site-packages\nicegui\middlewares.py", line 13, in dispatch
    response = await call_next(request)
               ^^^^^^^^^^^^^^^^^^^^^^^^
  File "C:\Users\Keila\AppData\Local\Programs\Python\Python311\Lib\site-packages\starlette\middleware\base.py", line 154, in call_next
    raise app_exc
  File "C:\Users\Keila\AppData\Local\Programs\Python\Python311\Lib\site-packages\starlette\middleware\base.py", line 141, in coro
    await self.app(scope, receive_or_disconnect, send_no_error)
  File "C:\Users\Keila\AppData\Local\Programs\Python\Python311\Lib\site-packages\starlette\middleware\gzip.py", line 20, in __call__
    await responder(scope, receive, send)
  File "C:\Users\Keila\AppData\Local\Programs\Python\Python311\Lib\site-packages\starlette\middleware\gzip.py", line 39, in __call__
    await self.app(scope, receive, self.send_with_gzip)
  File "C:\Users\Keila\AppData\Local\Programs\Python\Python311\Lib\site-packages\starlette\middleware\exceptions.py", line 62, in __call__
    await wrap_app_handling_exceptions(self.app, conn)(scope, receive, send)
  File "C:\Users\Keila\AppData\Local\Programs\Python\Python311\Lib\site-packages\starlette\_exception_handler.py", line 53, in wrapped_app
    raise exc
  File "C:\Users\Keila\AppData\Local\Programs\Python\Python311\Lib\site-packages\starlette\_exception_handler.py", line 42, in wrapped_app
    await app(scope, receive, sender)
  File "C:\Users\Keila\AppData\Local\Programs\Python\Python311\Lib\site-packages\starlette\routing.py", line 715, in __call__
    await self.middleware_stack(scope, receive, send)
  File "C:\Users\Keila\AppData\Local\Programs\Python\Python311\Lib\site-packages\starlette\routing.py", line 735, in app
    await route.handle(scope, receive, send)
  File "C:\Users\Keila\AppData\Local\Programs\Python\Python311\Lib\site-packages\starlette\routing.py", line 288, in handle
    await self.app(scope, receive, send)
  File "C:\Users\Keila\AppData\Local\Programs\Python\Python311\Lib\site-packages\starlette\routing.py", line 76, in app
    await wrap_app_handling_exceptions(app, request)(scope, receive, send)
  File "C:\Users\Keila\AppData\Local\Programs\Python\Python311\Lib\site-packages\starlette\_exception_handler.py", line 53, in wrapped_app
    raise exc
  File "C:\Users\Keila\AppData\Local\Programs\Python\Python311\Lib\site-packages\starlette\_exception_handler.py", line 42, in wrapped_app
    await app(scope, receive, sender)
  File "C:\Users\Keila\AppData\Local\Programs\Python\Python311\Lib\site-packages\starlette\routing.py", line 73, in app
    response = await f(request)
               ^^^^^^^^^^^^^^^^
  File "C:\Users\Keila\AppData\Local\Programs\Python\Python311\Lib\site-packages\fastapi\routing.py", line 301, in app
    raw_response = await run_endpoint_function(
                   ^^^^^^^^^^^^^^^^^^^^^^^^^^^^
  File "C:\Users\Keila\AppData\Local\Programs\Python\Python311\Lib\site-packages\fastapi\routing.py", line 212, in run_endpoint_function
    return await dependant.call(**values)
           ^^^^^^^^^^^^^^^^^^^^^^^^^^^^^^
  File "C:\Users\Keila\AppData\Local\Programs\Python\Python311\Lib\site-packages\nicegui\page.py", line 153, in decorated
    return create_error_page(e, request)
           ^^^^^^^^^^^^^^^^^^^^^^^^^^^^^
  File "C:\Users\Keila\AppData\Local\Programs\Python\Python311\Lib\site-packages\nicegui\page.py", line 116, in create_error_page
    raise e
  File "C:\Users\Keila\AppData\Local\Programs\Python\Python311\Lib\site-packages\nicegui\page.py", line 147, in decorated
    result = func(*dec_args, **dec_kwargs)
             ^^^^^^^^^^^^^^^^^^^^^^^^^^^^^
  File "c:\Users\Keila\Downloads\VehicleMax-main (1)\VehicleMax-main\VIN_Decoder\VIN-Decoder.py", line 29, in vin_decoder_page
    for url in app.urls:
               ^^^
NameError: name 'app' is not defined
ERROR:nicegui:name 'app' is not defined
  + Exception Group Traceback (most recent call last):
  |   File "C:\Users\Keila\AppData\Local\Programs\Python\Python311\Lib\site-packages\starlette\_utils.py", line 76, in collapse_excgroups
  |     yield
  |   File "C:\Users\Keila\AppData\Local\Programs\Python\Python311\Lib\site-packages\starlette\middleware\base.py", line 178, in __call__
  |     async with anyio.create_task_group() as task_group:
  |   File "C:\Users\Keila\AppData\Local\Programs\Python\Python311\Lib\site-packages\anyio\_backends\_asyncio.py", line 767, in __aexit__
  |     raise BaseExceptionGroup(
  | ExceptionGroup: unhandled errors in a TaskGroup (1 sub-exception)
  +-+---------------- 1 ----------------
    | Traceback (most recent call last):
    |   File "C:\Users\Keila\AppData\Local\Programs\Python\Python311\Lib\site-packages\starlette\middleware\errors.py", line 165, in __call__
    |     await self.app(scope, receive, _send)
    |   File "C:\Users\Keila\AppData\Local\Programs\Python\Python311\Lib\site-packages\starlette\middleware\base.py", line 177, in __call__
    |     with recv_stream, send_stream, collapse_excgroups():
    |   File "C:\Users\Keila\AppData\Local\Programs\Python\Python311\Lib\contextlib.py", line 155, in __exit__
    |     self.gen.throw(typ, value, traceback)
    |   File "C:\Users\Keila\AppData\Local\Programs\Python\Python311\Lib\site-packages\starlette\_utils.py", line 82, in collapse_excgroups
    |     raise exc
    |   File "C:\Users\Keila\AppData\Local\Programs\Python\Python311\Lib\site-packages\starlette\middleware\base.py", line 179, in __call__
    |     response = await self.dispatch_func(request, call_next)
    |                ^^^^^^^^^^^^^^^^^^^^^^^^^^^^^^^^^^^^^^^^^^^^
    |   File "C:\Users\Keila\AppData\Local\Programs\Python\Python311\Lib\site-packages\nicegui\middlewares.py", line 23, in dispatch
    |     response = await call_next(request)
    |                ^^^^^^^^^^^^^^^^^^^^^^^^
    |   File "C:\Users\Keila\AppData\Local\Programs\Python\Python311\Lib\site-packages\starlette\middleware\base.py", line 154, in call_next
    |     raise app_exc
    |   File "C:\Users\Keila\AppData\Local\Programs\Python\Python311\Lib\site-packages\starlette\middleware\base.py", line 141, in coro
    |     await self.app(scope, receive_or_disconnect, send_no_error)
    |   File "C:\Users\Keila\AppData\Local\Programs\Python\Python311\Lib\site-packages\starlette\middleware\base.py", line 177, in __call__
    |     with recv_stream, send_stream, collapse_excgroups():
    |   File "C:\Users\Keila\AppData\Local\Programs\Python\Python311\Lib\contextlib.py", line 155, in __exit__
    |     self.gen.throw(typ, value, traceback)
    |   File "C:\Users\Keila\AppData\Local\Programs\Python\Python311\Lib\site-packages\starlette\_utils.py", line 82, in collapse_excgroups
    |     raise exc
    |   File "C:\Users\Keila\AppData\Local\Programs\Python\Python311\Lib\site-packages\starlette\middleware\base.py", line 179, in __call__
    |     response = await self.dispatch_func(request, call_next)
    |                ^^^^^^^^^^^^^^^^^^^^^^^^^^^^^^^^^^^^^^^^^^^^
    |   File "C:\Users\Keila\AppData\Local\Programs\Python\Python311\Lib\site-packages\nicegui\middlewares.py", line 13, in dispatch
    |     response = await call_next(request)
    |                ^^^^^^^^^^^^^^^^^^^^^^^^
    |   File "C:\Users\Keila\AppData\Local\Programs\Python\Python311\Lib\site-packages\starlette\middleware\base.py", line 154, in call_next
    |     raise app_exc
    |   File "C:\Users\Keila\AppData\Local\Programs\Python\Python311\Lib\site-packages\starlette\middleware\base.py", line 141, in coro
    |     await self.app(scope, receive_or_disconnect, send_no_error)
    |   File "C:\Users\Keila\AppData\Local\Programs\Python\Python311\Lib\site-packages\starlette\middleware\gzip.py", line 20, in __call__
    |     await responder(scope, receive, send)
    |   File "C:\Users\Keila\AppData\Local\Programs\Python\Python311\Lib\site-packages\starlette\middleware\gzip.py", line 39, in __call__
    |     await self.app(scope, receive, self.send_with_gzip)
    |   File "C:\Users\Keila\AppData\Local\Programs\Python\Python311\Lib\site-packages\starlette\middleware\exceptions.py", line 62, in __call__
    |     await wrap_app_handling_exceptions(self.app, conn)(scope, receive, send)
    |   File "C:\Users\Keila\AppData\Local\Programs\Python\Python311\Lib\site-packages\starlette\_exception_handler.py", line 53, in wrapped_app
    |     raise exc
    |   File "C:\Users\Keila\AppData\Local\Programs\Python\Python311\Lib\site-packages\starlette\_exception_handler.py", line 42, in wrapped_app
    |     await app(scope, receive, sender)
    |   File "C:\Users\Keila\AppData\Local\Programs\Python\Python311\Lib\site-packages\starlette\routing.py", line 715, in __call__
    |     await self.middleware_stack(scope, receive, send)
    |   File "C:\Users\Keila\AppData\Local\Programs\Python\Python311\Lib\site-packages\starlette\routing.py", line 735, in app
    |     await route.handle(scope, receive, send)
    |   File "C:\Users\Keila\AppData\Local\Programs\Python\Python311\Lib\site-packages\starlette\routing.py", line 288, in handle
    |     await self.app(scope, receive, send)
    |   File "C:\Users\Keila\AppData\Local\Programs\Python\Python311\Lib\site-packages\starlette\routing.py", line 76, in app
    |     await wrap_app_handling_exceptions(app, request)(scope, receive, send)
    |   File "C:\Users\Keila\AppData\Local\Programs\Python\Python311\Lib\site-packages\starlette\_exception_handler.py", line 53, in wrapped_app
    |     raise exc
    |   File "C:\Users\Keila\AppData\Local\Programs\Python\Python311\Lib\site-packages\starlette\_exception_handler.py", line 42, in wrapped_app
    |     await app(scope, receive, sender)
    |   File "C:\Users\Keila\AppData\Local\Programs\Python\Python311\Lib\site-packages\starlette\routing.py", line 73, in app
    |     response = await f(request)
    |                ^^^^^^^^^^^^^^^^
    |   File "C:\Users\Keila\AppData\Local\Programs\Python\Python311\Lib\site-packages\fastapi\routing.py", line 301, in app
    |     raw_response = await run_endpoint_function(
    |                    ^^^^^^^^^^^^^^^^^^^^^^^^^^^^
    |   File "C:\Users\Keila\AppData\Local\Programs\Python\Python311\Lib\site-packages\fastapi\routing.py", line 212, in run_endpoint_function
    |     return await dependant.call(**values)
    |            ^^^^^^^^^^^^^^^^^^^^^^^^^^^^^^
    |   File "C:\Users\Keila\AppData\Local\Programs\Python\Python311\Lib\site-packages\nicegui\page.py", line 153, in decorated
    |     return create_error_page(e, request)
    |            ^^^^^^^^^^^^^^^^^^^^^^^^^^^^^
    |   File "C:\Users\Keila\AppData\Local\Programs\Python\Python311\Lib\site-packages\nicegui\page.py", line 116, in create_error_page
    |     raise e
    |   File "C:\Users\Keila\AppData\Local\Programs\Python\Python311\Lib\site-packages\nicegui\page.py", line 147, in decorated
    |     result = func(*dec_args, **dec_kwargs)
    |              ^^^^^^^^^^^^^^^^^^^^^^^^^^^^^
    |   File "c:\Users\Keila\Downloads\VehicleMax-main (1)\VehicleMax-main\VIN_Decoder\VIN-Decoder.py", line 29, in vin_decoder_page
    |     for url in app.urls:
    |                ^^^
    | NameError: name 'app' is not defined
    +------------------------------------

During handling of the above exception, another exception occurred:

Traceback (most recent call last):
  File "C:\Users\Keila\AppData\Local\Programs\Python\Python311\Lib\site-packages\starlette\middleware\errors.py", line 165, in __call__
    await self.app(scope, receive, _send)
  File "C:\Users\Keila\AppData\Local\Programs\Python\Python311\Lib\site-packages\starlette\middleware\base.py", line 177, in __call__
    with recv_stream, send_stream, collapse_excgroups():
  File "C:\Users\Keila\AppData\Local\Programs\Python\Python311\Lib\contextlib.py", line 155, in __exit__
    self.gen.throw(typ, value, traceback)
  File "C:\Users\Keila\AppData\Local\Programs\Python\Python311\Lib\site-packages\starlette\_utils.py", line 82, in collapse_excgroups
    raise exc
  File "C:\Users\Keila\AppData\Local\Programs\Python\Python311\Lib\site-packages\starlette\middleware\base.py", line 179, in __call__
    response = await self.dispatch_func(request, call_next)
               ^^^^^^^^^^^^^^^^^^^^^^^^^^^^^^^^^^^^^^^^^^^^
  File "C:\Users\Keila\AppData\Local\Programs\Python\Python311\Lib\site-packages\nicegui\middlewares.py", line 23, in dispatch
    response = await call_next(request)
               ^^^^^^^^^^^^^^^^^^^^^^^^
  File "C:\Users\Keila\AppData\Local\Programs\Python\Python311\Lib\site-packages\starlette\middleware\base.py", line 154, in call_next
    raise app_exc
  File "C:\Users\Keila\AppData\Local\Programs\Python\Python311\Lib\site-packages\starlette\middleware\base.py", line 141, in coro
    await self.app(scope, receive_or_disconnect, send_no_error)
  File "C:\Users\Keila\AppData\Local\Programs\Python\Python311\Lib\site-packages\starlette\middleware\base.py", line 177, in __call__
    with recv_stream, send_stream, collapse_excgroups():
  File "C:\Users\Keila\AppData\Local\Programs\Python\Python311\Lib\contextlib.py", line 155, in __exit__
    self.gen.throw(typ, value, traceback)
  File "C:\Users\Keila\AppData\Local\Programs\Python\Python311\Lib\site-packages\starlette\_utils.py", line 82, in collapse_excgroups
    raise exc
  File "C:\Users\Keila\AppData\Local\Programs\Python\Python311\Lib\site-packages\starlette\middleware\base.py", line 179, in __call__
    response = await self.dispatch_func(request, call_next)
               ^^^^^^^^^^^^^^^^^^^^^^^^^^^^^^^^^^^^^^^^^^^^
  File "C:\Users\Keila\AppData\Local\Programs\Python\Python311\Lib\site-packages\nicegui\middlewares.py", line 13, in dispatch
    response = await call_next(request)
               ^^^^^^^^^^^^^^^^^^^^^^^^
  File "C:\Users\Keila\AppData\Local\Programs\Python\Python311\Lib\site-packages\starlette\middleware\base.py", line 154, in call_next
    raise app_exc
  File "C:\Users\Keila\AppData\Local\Programs\Python\Python311\Lib\site-packages\starlette\middleware\base.py", line 141, in coro
    await self.app(scope, receive_or_disconnect, send_no_error)
  File "C:\Users\Keila\AppData\Local\Programs\Python\Python311\Lib\site-packages\starlette\middleware\gzip.py", line 20, in __call__
    await responder(scope, receive, send)
  File "C:\Users\Keila\AppData\Local\Programs\Python\Python311\Lib\site-packages\starlette\middleware\gzip.py", line 39, in __call__
    await self.app(scope, receive, self.send_with_gzip)
  File "C:\Users\Keila\AppData\Local\Programs\Python\Python311\Lib\site-packages\starlette\middleware\exceptions.py", line 62, in __call__
    await wrap_app_handling_exceptions(self.app, conn)(scope, receive, send)
  File "C:\Users\Keila\AppData\Local\Programs\Python\Python311\Lib\site-packages\starlette\_exception_handler.py", line 53, in wrapped_app
    raise exc
  File "C:\Users\Keila\AppData\Local\Programs\Python\Python311\Lib\site-packages\starlette\_exception_handler.py", line 42, in wrapped_app
    await app(scope, receive, sender)
  File "C:\Users\Keila\AppData\Local\Programs\Python\Python311\Lib\site-packages\starlette\routing.py", line 715, in __call__
    await self.middleware_stack(scope, receive, send)
  File "C:\Users\Keila\AppData\Local\Programs\Python\Python311\Lib\site-packages\starlette\routing.py", line 735, in app
    await route.handle(scope, receive, send)
  File "C:\Users\Keila\AppData\Local\Programs\Python\Python311\Lib\site-packages\starlette\routing.py", line 288, in handle
    await self.app(scope, receive, send)
  File "C:\Users\Keila\AppData\Local\Programs\Python\Python311\Lib\site-packages\starlette\routing.py", line 76, in app
    await wrap_app_handling_exceptions(app, request)(scope, receive, send)
  File "C:\Users\Keila\AppData\Local\Programs\Python\Python311\Lib\site-packages\starlette\_exception_handler.py", line 53, in wrapped_app
    raise exc
  File "C:\Users\Keila\AppData\Local\Programs\Python\Python311\Lib\site-packages\starlette\_exception_handler.py", line 42, in wrapped_app
    await app(scope, receive, sender)
  File "C:\Users\Keila\AppData\Local\Programs\Python\Python311\Lib\site-packages\starlette\routing.py", line 73, in app
    response = await f(request)
               ^^^^^^^^^^^^^^^^
  File "C:\Users\Keila\AppData\Local\Programs\Python\Python311\Lib\site-packages\fastapi\routing.py", line 301, in app
    raw_response = await run_endpoint_function(
                   ^^^^^^^^^^^^^^^^^^^^^^^^^^^^
  File "C:\Users\Keila\AppData\Local\Programs\Python\Python311\Lib\site-packages\fastapi\routing.py", line 212, in run_endpoint_function
    return await dependant.call(**values)
           ^^^^^^^^^^^^^^^^^^^^^^^^^^^^^^
  File "C:\Users\Keila\AppData\Local\Programs\Python\Python311\Lib\site-packages\nicegui\page.py", line 153, in decorated
    return create_error_page(e, request)
           ^^^^^^^^^^^^^^^^^^^^^^^^^^^^^
  File "C:\Users\Keila\AppData\Local\Programs\Python\Python311\Lib\site-packages\nicegui\page.py", line 116, in create_error_page
    raise e
  File "C:\Users\Keila\AppData\Local\Programs\Python\Python311\Lib\site-packages\nicegui\page.py", line 147, in decorated
    result = func(*dec_args, **dec_kwargs)
             ^^^^^^^^^^^^^^^^^^^^^^^^^^^^^
  File "c:\Users\Keila\Downloads\VehicleMax-main (1)\VehicleMax-main\VIN_Decoder\VIN-Decoder.py", line 29, in vin_decoder_page
    for url in app.urls:
               ^^^
NameError: name 'app' is not defined
ERROR:nicegui:name 'app' is not defined
  + Exception Group Traceback (most recent call last):
  |   File "C:\Users\Keila\AppData\Local\Programs\Python\Python311\Lib\site-packages\starlette\_utils.py", line 76, in collapse_excgroups
  |     yield
  |   File "C:\Users\Keila\AppData\Local\Programs\Python\Python311\Lib\site-packages\starlette\middleware\base.py", line 178, in __call__
  |     async with anyio.create_task_group() as task_group:
  |   File "C:\Users\Keila\AppData\Local\Programs\Python\Python311\Lib\site-packages\anyio\_backends\_asyncio.py", line 767, in __aexit__
  |     raise BaseExceptionGroup(
  | ExceptionGroup: unhandled errors in a TaskGroup (1 sub-exception)
  +-+---------------- 1 ----------------
    | Traceback (most recent call last):
    |   File "C:\Users\Keila\AppData\Local\Programs\Python\Python311\Lib\site-packages\starlette\middleware\errors.py", line 165, in __call__
    |     await self.app(scope, receive, _send)
    |   File "C:\Users\Keila\AppData\Local\Programs\Python\Python311\Lib\site-packages\starlette\middleware\base.py", line 177, in __call__
    |     with recv_stream, send_stream, collapse_excgroups():
    |   File "C:\Users\Keila\AppData\Local\Programs\Python\Python311\Lib\contextlib.py", line 155, in __exit__
    |     self.gen.throw(typ, value, traceback)
    |   File "C:\Users\Keila\AppData\Local\Programs\Python\Python311\Lib\site-packages\starlette\_utils.py", line 82, in collapse_excgroups
    |     raise exc
    |   File "C:\Users\Keila\AppData\Local\Programs\Python\Python311\Lib\site-packages\starlette\middleware\base.py", line 179, in __call__
    |     response = await self.dispatch_func(request, call_next)
    |                ^^^^^^^^^^^^^^^^^^^^^^^^^^^^^^^^^^^^^^^^^^^^
    |   File "C:\Users\Keila\AppData\Local\Programs\Python\Python311\Lib\site-packages\nicegui\middlewares.py", line 23, in dispatch
    |     response = await call_next(request)
    |                ^^^^^^^^^^^^^^^^^^^^^^^^
    |   File "C:\Users\Keila\AppData\Local\Programs\Python\Python311\Lib\site-packages\starlette\middleware\base.py", line 154, in call_next
    |     raise app_exc
    |   File "C:\Users\Keila\AppData\Local\Programs\Python\Python311\Lib\site-packages\starlette\middleware\base.py", line 141, in coro
    |     await self.app(scope, receive_or_disconnect, send_no_error)
    |   File "C:\Users\Keila\AppData\Local\Programs\Python\Python311\Lib\site-packages\starlette\middleware\base.py", line 177, in __call__
    |     with recv_stream, send_stream, collapse_excgroups():
    |   File "C:\Users\Keila\AppData\Local\Programs\Python\Python311\Lib\contextlib.py", line 155, in __exit__
    |     self.gen.throw(typ, value, traceback)
    |   File "C:\Users\Keila\AppData\Local\Programs\Python\Python311\Lib\site-packages\starlette\_utils.py", line 82, in collapse_excgroups
    |     raise exc
    |   File "C:\Users\Keila\AppData\Local\Programs\Python\Python311\Lib\site-packages\starlette\middleware\base.py", line 179, in __call__
    |     response = await self.dispatch_func(request, call_next)
    |                ^^^^^^^^^^^^^^^^^^^^^^^^^^^^^^^^^^^^^^^^^^^^
    |   File "C:\Users\Keila\AppData\Local\Programs\Python\Python311\Lib\site-packages\nicegui\middlewares.py", line 13, in dispatch
    |     response = await call_next(request)
    |                ^^^^^^^^^^^^^^^^^^^^^^^^
    |   File "C:\Users\Keila\AppData\Local\Programs\Python\Python311\Lib\site-packages\starlette\middleware\base.py", line 154, in call_next
    |     raise app_exc
    |   File "C:\Users\Keila\AppData\Local\Programs\Python\Python311\Lib\site-packages\starlette\middleware\base.py", line 141, in coro
    |     await self.app(scope, receive_or_disconnect, send_no_error)
    |   File "C:\Users\Keila\AppData\Local\Programs\Python\Python311\Lib\site-packages\starlette\middleware\gzip.py", line 20, in __call__
    |     await responder(scope, receive, send)
    |   File "C:\Users\Keila\AppData\Local\Programs\Python\Python311\Lib\site-packages\starlette\middleware\gzip.py", line 39, in __call__
    |     await self.app(scope, receive, self.send_with_gzip)
    |   File "C:\Users\Keila\AppData\Local\Programs\Python\Python311\Lib\site-packages\starlette\middleware\exceptions.py", line 62, in __call__
    |     await wrap_app_handling_exceptions(self.app, conn)(scope, receive, send)
    |   File "C:\Users\Keila\AppData\Local\Programs\Python\Python311\Lib\site-packages\starlette\_exception_handler.py", line 53, in wrapped_app
    |     raise exc
    |   File "C:\Users\Keila\AppData\Local\Programs\Python\Python311\Lib\site-packages\starlette\_exception_handler.py", line 42, in wrapped_app
    |     await app(scope, receive, sender)
    |   File "C:\Users\Keila\AppData\Local\Programs\Python\Python311\Lib\site-packages\starlette\routing.py", line 715, in __call__
    |     await self.middleware_stack(scope, receive, send)
    |   File "C:\Users\Keila\AppData\Local\Programs\Python\Python311\Lib\site-packages\starlette\routing.py", line 735, in app
    |     await route.handle(scope, receive, send)
    |   File "C:\Users\Keila\AppData\Local\Programs\Python\Python311\Lib\site-packages\starlette\routing.py", line 288, in handle
    |     await self.app(scope, receive, send)
    |   File "C:\Users\Keila\AppData\Local\Programs\Python\Python311\Lib\site-packages\starlette\routing.py", line 76, in app
    |     await wrap_app_handling_exceptions(app, request)(scope, receive, send)
    |   File "C:\Users\Keila\AppData\Local\Programs\Python\Python311\Lib\site-packages\starlette\_exception_handler.py", line 53, in wrapped_app
    |     raise exc
    |   File "C:\Users\Keila\AppData\Local\Programs\Python\Python311\Lib\site-packages\starlette\_exception_handler.py", line 42, in wrapped_app
    |     await app(scope, receive, sender)
    |   File "C:\Users\Keila\AppData\Local\Programs\Python\Python311\Lib\site-packages\starlette\routing.py", line 73, in app
    |     response = await f(request)
    |                ^^^^^^^^^^^^^^^^
    |   File "C:\Users\Keila\AppData\Local\Programs\Python\Python311\Lib\site-packages\fastapi\routing.py", line 301, in app
    |     raw_response = await run_endpoint_function(
    |                    ^^^^^^^^^^^^^^^^^^^^^^^^^^^^
    |   File "C:\Users\Keila\AppData\Local\Programs\Python\Python311\Lib\site-packages\fastapi\routing.py", line 212, in run_endpoint_function
    |     return await dependant.call(**values)
    |            ^^^^^^^^^^^^^^^^^^^^^^^^^^^^^^
    |   File "C:\Users\Keila\AppData\Local\Programs\Python\Python311\Lib\site-packages\nicegui\page.py", line 153, in decorated
    |     return create_error_page(e, request)
    |            ^^^^^^^^^^^^^^^^^^^^^^^^^^^^^
    |   File "C:\Users\Keila\AppData\Local\Programs\Python\Python311\Lib\site-packages\nicegui\page.py", line 116, in create_error_page
    |     raise e
    |   File "C:\Users\Keila\AppData\Local\Programs\Python\Python311\Lib\site-packages\nicegui\page.py", line 147, in decorated
    |     result = func(*dec_args, **dec_kwargs)
    |              ^^^^^^^^^^^^^^^^^^^^^^^^^^^^^
    |   File "c:\Users\Keila\Downloads\VehicleMax-main (1)\VehicleMax-main\VIN_Decoder\VIN-Decoder.py", line 29, in vin_decoder_page
    |     for url in app.urls:
    |                ^^^
    | NameError: name 'app' is not defined
    +------------------------------------

During handling of the above exception, another exception occurred:

Traceback (most recent call last):
  File "C:\Users\Keila\AppData\Local\Programs\Python\Python311\Lib\site-packages\starlette\middleware\errors.py", line 165, in __call__
    await self.app(scope, receive, _send)
  File "C:\Users\Keila\AppData\Local\Programs\Python\Python311\Lib\site-packages\starlette\middleware\base.py", line 177, in __call__
    with recv_stream, send_stream, collapse_excgroups():
  File "C:\Users\Keila\AppData\Local\Programs\Python\Python311\Lib\contextlib.py", line 155, in __exit__
    self.gen.throw(typ, value, traceback)
  File "C:\Users\Keila\AppData\Local\Programs\Python\Python311\Lib\site-packages\starlette\_utils.py", line 82, in collapse_excgroups
    raise exc
  File "C:\Users\Keila\AppData\Local\Programs\Python\Python311\Lib\site-packages\starlette\middleware\base.py", line 179, in __call__
    response = await self.dispatch_func(request, call_next)
               ^^^^^^^^^^^^^^^^^^^^^^^^^^^^^^^^^^^^^^^^^^^^
  File "C:\Users\Keila\AppData\Local\Programs\Python\Python311\Lib\site-packages\nicegui\middlewares.py", line 23, in dispatch
    response = await call_next(request)
               ^^^^^^^^^^^^^^^^^^^^^^^^
  File "C:\Users\Keila\AppData\Local\Programs\Python\Python311\Lib\site-packages\starlette\middleware\base.py", line 154, in call_next
    raise app_exc
  File "C:\Users\Keila\AppData\Local\Programs\Python\Python311\Lib\site-packages\starlette\middleware\base.py", line 141, in coro
    await self.app(scope, receive_or_disconnect, send_no_error)
  File "C:\Users\Keila\AppData\Local\Programs\Python\Python311\Lib\site-packages\starlette\middleware\base.py", line 177, in __call__
    with recv_stream, send_stream, collapse_excgroups():
  File "C:\Users\Keila\AppData\Local\Programs\Python\Python311\Lib\contextlib.py", line 155, in __exit__
    self.gen.throw(typ, value, traceback)
  File "C:\Users\Keila\AppData\Local\Programs\Python\Python311\Lib\site-packages\starlette\_utils.py", line 82, in collapse_excgroups
    raise exc
  File "C:\Users\Keila\AppData\Local\Programs\Python\Python311\Lib\site-packages\starlette\middleware\base.py", line 179, in __call__
    response = await self.dispatch_func(request, call_next)
               ^^^^^^^^^^^^^^^^^^^^^^^^^^^^^^^^^^^^^^^^^^^^
  File "C:\Users\Keila\AppData\Local\Programs\Python\Python311\Lib\site-packages\nicegui\middlewares.py", line 13, in dispatch
    response = await call_next(request)
               ^^^^^^^^^^^^^^^^^^^^^^^^
  File "C:\Users\Keila\AppData\Local\Programs\Python\Python311\Lib\site-packages\starlette\middleware\base.py", line 154, in call_next
    raise app_exc
  File "C:\Users\Keila\AppData\Local\Programs\Python\Python311\Lib\site-packages\starlette\middleware\base.py", line 141, in coro
    await self.app(scope, receive_or_disconnect, send_no_error)
  File "C:\Users\Keila\AppData\Local\Programs\Python\Python311\Lib\site-packages\starlette\middleware\gzip.py", line 20, in __call__
    await responder(scope, receive, send)
  File "C:\Users\Keila\AppData\Local\Programs\Python\Python311\Lib\site-packages\starlette\middleware\gzip.py", line 39, in __call__
    await self.app(scope, receive, self.send_with_gzip)
  File "C:\Users\Keila\AppData\Local\Programs\Python\Python311\Lib\site-packages\starlette\middleware\exceptions.py", line 62, in __call__
    await wrap_app_handling_exceptions(self.app, conn)(scope, receive, send)
  File "C:\Users\Keila\AppData\Local\Programs\Python\Python311\Lib\site-packages\starlette\_exception_handler.py", line 53, in wrapped_app
    raise exc
  File "C:\Users\Keila\AppData\Local\Programs\Python\Python311\Lib\site-packages\starlette\_exception_handler.py", line 42, in wrapped_app
    await app(scope, receive, sender)
  File "C:\Users\Keila\AppData\Local\Programs\Python\Python311\Lib\site-packages\starlette\routing.py", line 715, in __call__
    await self.middleware_stack(scope, receive, send)
  File "C:\Users\Keila\AppData\Local\Programs\Python\Python311\Lib\site-packages\starlette\routing.py", line 735, in app
    await route.handle(scope, receive, send)
  File "C:\Users\Keila\AppData\Local\Programs\Python\Python311\Lib\site-packages\starlette\routing.py", line 288, in handle
    await self.app(scope, receive, send)
  File "C:\Users\Keila\AppData\Local\Programs\Python\Python311\Lib\site-packages\starlette\routing.py", line 76, in app
    await wrap_app_handling_exceptions(app, request)(scope, receive, send)
  File "C:\Users\Keila\AppData\Local\Programs\Python\Python311\Lib\site-packages\starlette\_exception_handler.py", line 53, in wrapped_app
    raise exc
  File "C:\Users\Keila\AppData\Local\Programs\Python\Python311\Lib\site-packages\starlette\_exception_handler.py", line 42, in wrapped_app
    await app(scope, receive, sender)
  File "C:\Users\Keila\AppData\Local\Programs\Python\Python311\Lib\site-packages\starlette\routing.py", line 73, in app
    response = await f(request)
               ^^^^^^^^^^^^^^^^
  File "C:\Users\Keila\AppData\Local\Programs\Python\Python311\Lib\site-packages\fastapi\routing.py", line 301, in app
    raw_response = await run_endpoint_function(
                   ^^^^^^^^^^^^^^^^^^^^^^^^^^^^
  File "C:\Users\Keila\AppData\Local\Programs\Python\Python311\Lib\site-packages\fastapi\routing.py", line 212, in run_endpoint_function
    return await dependant.call(**values)
           ^^^^^^^^^^^^^^^^^^^^^^^^^^^^^^
  File "C:\Users\Keila\AppData\Local\Programs\Python\Python311\Lib\site-packages\nicegui\page.py", line 153, in decorated
    return create_error_page(e, request)
           ^^^^^^^^^^^^^^^^^^^^^^^^^^^^^
  File "C:\Users\Keila\AppData\Local\Programs\Python\Python311\Lib\site-packages\nicegui\page.py", line 116, in create_error_page
    raise e
  File "C:\Users\Keila\AppData\Local\Programs\Python\Python311\Lib\site-packages\nicegui\page.py", line 147, in decorated
    result = func(*dec_args, **dec_kwargs)
             ^^^^^^^^^^^^^^^^^^^^^^^^^^^^^
  File "c:\Users\Keila\Downloads\VehicleMax-main (1)\VehicleMax-main\VIN_Decoder\VIN-Decoder.py", line 29, in vin_decoder_page
    for url in app.urls:
               ^^^
NameError: name 'app' is not defined
ERROR:nicegui:name 'app' is not defined
  + Exception Group Traceback (most recent call last):
  |   File "C:\Users\Keila\AppData\Local\Programs\Python\Python311\Lib\site-packages\starlette\_utils.py", line 76, in collapse_excgroups
  |     yield
  |   File "C:\Users\Keila\AppData\Local\Programs\Python\Python311\Lib\site-packages\starlette\middleware\base.py", line 178, in __call__
  |     async with anyio.create_task_group() as task_group:
  |   File "C:\Users\Keila\AppData\Local\Programs\Python\Python311\Lib\site-packages\anyio\_backends\_asyncio.py", line 767, in __aexit__
  |     raise BaseExceptionGroup(
  | ExceptionGroup: unhandled errors in a TaskGroup (1 sub-exception)
  +-+---------------- 1 ----------------
    | Traceback (most recent call last):
    |   File "C:\Users\Keila\AppData\Local\Programs\Python\Python311\Lib\site-packages\starlette\middleware\errors.py", line 165, in __call__
    |     await self.app(scope, receive, _send)
    |   File "C:\Users\Keila\AppData\Local\Programs\Python\Python311\Lib\site-packages\starlette\middleware\base.py", line 177, in __call__
    |     with recv_stream, send_stream, collapse_excgroups():
    |   File "C:\Users\Keila\AppData\Local\Programs\Python\Python311\Lib\contextlib.py", line 155, in __exit__
    |     self.gen.throw(typ, value, traceback)
    |   File "C:\Users\Keila\AppData\Local\Programs\Python\Python311\Lib\site-packages\starlette\_utils.py", line 82, in collapse_excgroups
    |     raise exc
    |   File "C:\Users\Keila\AppData\Local\Programs\Python\Python311\Lib\site-packages\starlette\middleware\base.py", line 179, in __call__
    |     response = await self.dispatch_func(request, call_next)
    |                ^^^^^^^^^^^^^^^^^^^^^^^^^^^^^^^^^^^^^^^^^^^^
    |   File "C:\Users\Keila\AppData\Local\Programs\Python\Python311\Lib\site-packages\nicegui\middlewares.py", line 23, in dispatch
    |     response = await call_next(request)
    |                ^^^^^^^^^^^^^^^^^^^^^^^^
    |   File "C:\Users\Keila\AppData\Local\Programs\Python\Python311\Lib\site-packages\starlette\middleware\base.py", line 154, in call_next
    |     raise app_exc
    |   File "C:\Users\Keila\AppData\Local\Programs\Python\Python311\Lib\site-packages\starlette\middleware\base.py", line 141, in coro
    |     await self.app(scope, receive_or_disconnect, send_no_error)
    |   File "C:\Users\Keila\AppData\Local\Programs\Python\Python311\Lib\site-packages\starlette\middleware\base.py", line 177, in __call__
    |     with recv_stream, send_stream, collapse_excgroups():
    |   File "C:\Users\Keila\AppData\Local\Programs\Python\Python311\Lib\contextlib.py", line 155, in __exit__
    |     self.gen.throw(typ, value, traceback)
    |   File "C:\Users\Keila\AppData\Local\Programs\Python\Python311\Lib\site-packages\starlette\_utils.py", line 82, in collapse_excgroups
    |     raise exc
    |   File "C:\Users\Keila\AppData\Local\Programs\Python\Python311\Lib\site-packages\starlette\middleware\base.py", line 179, in __call__
    |     response = await self.dispatch_func(request, call_next)
    |                ^^^^^^^^^^^^^^^^^^^^^^^^^^^^^^^^^^^^^^^^^^^^
    |   File "C:\Users\Keila\AppData\Local\Programs\Python\Python311\Lib\site-packages\nicegui\middlewares.py", line 13, in dispatch
    |     response = await call_next(request)
    |                ^^^^^^^^^^^^^^^^^^^^^^^^
    |   File "C:\Users\Keila\AppData\Local\Programs\Python\Python311\Lib\site-packages\starlette\middleware\base.py", line 154, in call_next
    |     raise app_exc
    |   File "C:\Users\Keila\AppData\Local\Programs\Python\Python311\Lib\site-packages\starlette\middleware\base.py", line 141, in coro
    |     await self.app(scope, receive_or_disconnect, send_no_error)
    |   File "C:\Users\Keila\AppData\Local\Programs\Python\Python311\Lib\site-packages\starlette\middleware\gzip.py", line 20, in __call__
    |     await responder(scope, receive, send)
    |   File "C:\Users\Keila\AppData\Local\Programs\Python\Python311\Lib\site-packages\starlette\middleware\gzip.py", line 39, in __call__
    |     await self.app(scope, receive, self.send_with_gzip)
    |   File "C:\Users\Keila\AppData\Local\Programs\Python\Python311\Lib\site-packages\starlette\middleware\exceptions.py", line 62, in __call__
    |     await wrap_app_handling_exceptions(self.app, conn)(scope, receive, send)
    |   File "C:\Users\Keila\AppData\Local\Programs\Python\Python311\Lib\site-packages\starlette\_exception_handler.py", line 53, in wrapped_app
    |     raise exc
    |   File "C:\Users\Keila\AppData\Local\Programs\Python\Python311\Lib\site-packages\starlette\_exception_handler.py", line 42, in wrapped_app
    |     await app(scope, receive, sender)
    |   File "C:\Users\Keila\AppData\Local\Programs\Python\Python311\Lib\site-packages\starlette\routing.py", line 715, in __call__
    |     await self.middleware_stack(scope, receive, send)
    |   File "C:\Users\Keila\AppData\Local\Programs\Python\Python311\Lib\site-packages\starlette\routing.py", line 735, in app
    |     await route.handle(scope, receive, send)
    |   File "C:\Users\Keila\AppData\Local\Programs\Python\Python311\Lib\site-packages\starlette\routing.py", line 288, in handle
    |     await self.app(scope, receive, send)
    |   File "C:\Users\Keila\AppData\Local\Programs\Python\Python311\Lib\site-packages\starlette\routing.py", line 76, in app
    |     await wrap_app_handling_exceptions(app, request)(scope, receive, send)
    |   File "C:\Users\Keila\AppData\Local\Programs\Python\Python311\Lib\site-packages\starlette\_exception_handler.py", line 53, in wrapped_app
    |     raise exc
    |   File "C:\Users\Keila\AppData\Local\Programs\Python\Python311\Lib\site-packages\starlette\_exception_handler.py", line 42, in wrapped_app
    |     await app(scope, receive, sender)
    |   File "C:\Users\Keila\AppData\Local\Programs\Python\Python311\Lib\site-packages\starlette\routing.py", line 73, in app
    |     response = await f(request)
    |                ^^^^^^^^^^^^^^^^
    |   File "C:\Users\Keila\AppData\Local\Programs\Python\Python311\Lib\site-packages\fastapi\routing.py", line 301, in app
    |     raw_response = await run_endpoint_function(
    |                    ^^^^^^^^^^^^^^^^^^^^^^^^^^^^
    |   File "C:\Users\Keila\AppData\Local\Programs\Python\Python311\Lib\site-packages\fastapi\routing.py", line 212, in run_endpoint_function
    |     return await dependant.call(**values)
    |            ^^^^^^^^^^^^^^^^^^^^^^^^^^^^^^
    |   File "C:\Users\Keila\AppData\Local\Programs\Python\Python311\Lib\site-packages\nicegui\page.py", line 153, in decorated
    |     return create_error_page(e, request)
    |            ^^^^^^^^^^^^^^^^^^^^^^^^^^^^^
    |   File "C:\Users\Keila\AppData\Local\Programs\Python\Python311\Lib\site-packages\nicegui\page.py", line 116, in create_error_page
    |     raise e
    |   File "C:\Users\Keila\AppData\Local\Programs\Python\Python311\Lib\site-packages\nicegui\page.py", line 147, in decorated
    |     result = func(*dec_args, **dec_kwargs)
    |              ^^^^^^^^^^^^^^^^^^^^^^^^^^^^^
    |   File "c:\Users\Keila\Downloads\VehicleMax-main (1)\VehicleMax-main\VIN_Decoder\VIN-Decoder.py", line 29, in vin_decoder_page
    |     for url in app.urls:
    |                ^^^
    | NameError: name 'app' is not defined
    +------------------------------------

During handling of the above exception, another exception occurred:

Traceback (most recent call last):
  File "C:\Users\Keila\AppData\Local\Programs\Python\Python311\Lib\site-packages\starlette\middleware\errors.py", line 165, in __call__
    await self.app(scope, receive, _send)
  File "C:\Users\Keila\AppData\Local\Programs\Python\Python311\Lib\site-packages\starlette\middleware\base.py", line 177, in __call__
    with recv_stream, send_stream, collapse_excgroups():
  File "C:\Users\Keila\AppData\Local\Programs\Python\Python311\Lib\contextlib.py", line 155, in __exit__
    self.gen.throw(typ, value, traceback)
  File "C:\Users\Keila\AppData\Local\Programs\Python\Python311\Lib\site-packages\starlette\_utils.py", line 82, in collapse_excgroups
    raise exc
  File "C:\Users\Keila\AppData\Local\Programs\Python\Python311\Lib\site-packages\starlette\middleware\base.py", line 179, in __call__
    response = await self.dispatch_func(request, call_next)
               ^^^^^^^^^^^^^^^^^^^^^^^^^^^^^^^^^^^^^^^^^^^^
  File "C:\Users\Keila\AppData\Local\Programs\Python\Python311\Lib\site-packages\nicegui\middlewares.py", line 23, in dispatch
    response = await call_next(request)
               ^^^^^^^^^^^^^^^^^^^^^^^^
  File "C:\Users\Keila\AppData\Local\Programs\Python\Python311\Lib\site-packages\starlette\middleware\base.py", line 154, in call_next
    raise app_exc
  File "C:\Users\Keila\AppData\Local\Programs\Python\Python311\Lib\site-packages\starlette\middleware\base.py", line 141, in coro
    await self.app(scope, receive_or_disconnect, send_no_error)
  File "C:\Users\Keila\AppData\Local\Programs\Python\Python311\Lib\site-packages\starlette\middleware\base.py", line 177, in __call__
    with recv_stream, send_stream, collapse_excgroups():
  File "C:\Users\Keila\AppData\Local\Programs\Python\Python311\Lib\contextlib.py", line 155, in __exit__
    self.gen.throw(typ, value, traceback)
  File "C:\Users\Keila\AppData\Local\Programs\Python\Python311\Lib\site-packages\starlette\_utils.py", line 82, in collapse_excgroups
    raise exc
  File "C:\Users\Keila\AppData\Local\Programs\Python\Python311\Lib\site-packages\starlette\middleware\base.py", line 179, in __call__
    response = await self.dispatch_func(request, call_next)
               ^^^^^^^^^^^^^^^^^^^^^^^^^^^^^^^^^^^^^^^^^^^^
  File "C:\Users\Keila\AppData\Local\Programs\Python\Python311\Lib\site-packages\nicegui\middlewares.py", line 13, in dispatch
    response = await call_next(request)
               ^^^^^^^^^^^^^^^^^^^^^^^^
  File "C:\Users\Keila\AppData\Local\Programs\Python\Python311\Lib\site-packages\starlette\middleware\base.py", line 154, in call_next
    raise app_exc
  File "C:\Users\Keila\AppData\Local\Programs\Python\Python311\Lib\site-packages\starlette\middleware\base.py", line 141, in coro
    await self.app(scope, receive_or_disconnect, send_no_error)
  File "C:\Users\Keila\AppData\Local\Programs\Python\Python311\Lib\site-packages\starlette\middleware\gzip.py", line 20, in __call__
    await responder(scope, receive, send)
  File "C:\Users\Keila\AppData\Local\Programs\Python\Python311\Lib\site-packages\starlette\middleware\gzip.py", line 39, in __call__
    await self.app(scope, receive, self.send_with_gzip)
  File "C:\Users\Keila\AppData\Local\Programs\Python\Python311\Lib\site-packages\starlette\middleware\exceptions.py", line 62, in __call__
    await wrap_app_handling_exceptions(self.app, conn)(scope, receive, send)
  File "C:\Users\Keila\AppData\Local\Programs\Python\Python311\Lib\site-packages\starlette\_exception_handler.py", line 53, in wrapped_app
    raise exc
  File "C:\Users\Keila\AppData\Local\Programs\Python\Python311\Lib\site-packages\starlette\_exception_handler.py", line 42, in wrapped_app
    await app(scope, receive, sender)
  File "C:\Users\Keila\AppData\Local\Programs\Python\Python311\Lib\site-packages\starlette\routing.py", line 715, in __call__
    await self.middleware_stack(scope, receive, send)
  File "C:\Users\Keila\AppData\Local\Programs\Python\Python311\Lib\site-packages\starlette\routing.py", line 735, in app
    await route.handle(scope, receive, send)
  File "C:\Users\Keila\AppData\Local\Programs\Python\Python311\Lib\site-packages\starlette\routing.py", line 288, in handle
    await self.app(scope, receive, send)
  File "C:\Users\Keila\AppData\Local\Programs\Python\Python311\Lib\site-packages\starlette\routing.py", line 76, in app
    await wrap_app_handling_exceptions(app, request)(scope, receive, send)
  File "C:\Users\Keila\AppData\Local\Programs\Python\Python311\Lib\site-packages\starlette\_exception_handler.py", line 53, in wrapped_app
    raise exc
  File "C:\Users\Keila\AppData\Local\Programs\Python\Python311\Lib\site-packages\starlette\_exception_handler.py", line 42, in wrapped_app
    await app(scope, receive, sender)
  File "C:\Users\Keila\AppData\Local\Programs\Python\Python311\Lib\site-packages\starlette\routing.py", line 73, in app
    response = await f(request)
               ^^^^^^^^^^^^^^^^
  File "C:\Users\Keila\AppData\Local\Programs\Python\Python311\Lib\site-packages\fastapi\routing.py", line 301, in app
    raw_response = await run_endpoint_function(
                   ^^^^^^^^^^^^^^^^^^^^^^^^^^^^
  File "C:\Users\Keila\AppData\Local\Programs\Python\Python311\Lib\site-packages\fastapi\routing.py", line 212, in run_endpoint_function
    return await dependant.call(**values)
           ^^^^^^^^^^^^^^^^^^^^^^^^^^^^^^
  File "C:\Users\Keila\AppData\Local\Programs\Python\Python311\Lib\site-packages\nicegui\page.py", line 153, in decorated
    return create_error_page(e, request)
           ^^^^^^^^^^^^^^^^^^^^^^^^^^^^^
  File "C:\Users\Keila\AppData\Local\Programs\Python\Python311\Lib\site-packages\nicegui\page.py", line 116, in create_error_page
    raise e
  File "C:\Users\Keila\AppData\Local\Programs\Python\Python311\Lib\site-packages\nicegui\page.py", line 147, in decorated
    result = func(*dec_args, **dec_kwargs)
             ^^^^^^^^^^^^^^^^^^^^^^^^^^^^^
  File "c:\Users\Keila\Downloads\VehicleMax-main (1)\VehicleMax-main\VIN_Decoder\VIN-Decoder.py", line 29, in vin_decoder_page
    for url in app.urls:
               ^^^
NameError: name 'app' is not defined
ERROR:nicegui:name 'app' is not defined
  + Exception Group Traceback (most recent call last):
  |   File "C:\Users\Keila\AppData\Local\Programs\Python\Python311\Lib\site-packages\starlette\_utils.py", line 76, in collapse_excgroups
  |     yield
  |   File "C:\Users\Keila\AppData\Local\Programs\Python\Python311\Lib\site-packages\starlette\middleware\base.py", line 178, in __call__
  |     async with anyio.create_task_group() as task_group:
  |   File "C:\Users\Keila\AppData\Local\Programs\Python\Python311\Lib\site-packages\anyio\_backends\_asyncio.py", line 767, in __aexit__
  |     raise BaseExceptionGroup(
  | ExceptionGroup: unhandled errors in a TaskGroup (1 sub-exception)
  +-+---------------- 1 ----------------
    | Traceback (most recent call last):
    |   File "C:\Users\Keila\AppData\Local\Programs\Python\Python311\Lib\site-packages\starlette\middleware\errors.py", line 165, in __call__
    |     await self.app(scope, receive, _send)
    |   File "C:\Users\Keila\AppData\Local\Programs\Python\Python311\Lib\site-packages\starlette\middleware\base.py", line 177, in __call__
    |     with recv_stream, send_stream, collapse_excgroups():
    |   File "C:\Users\Keila\AppData\Local\Programs\Python\Python311\Lib\contextlib.py", line 155, in __exit__
    |     self.gen.throw(typ, value, traceback)
    |   File "C:\Users\Keila\AppData\Local\Programs\Python\Python311\Lib\site-packages\starlette\_utils.py", line 82, in collapse_excgroups
    |     raise exc
    |   File "C:\Users\Keila\AppData\Local\Programs\Python\Python311\Lib\site-packages\starlette\middleware\base.py", line 179, in __call__
    |     response = await self.dispatch_func(request, call_next)
    |                ^^^^^^^^^^^^^^^^^^^^^^^^^^^^^^^^^^^^^^^^^^^^
    |   File "C:\Users\Keila\AppData\Local\Programs\Python\Python311\Lib\site-packages\nicegui\middlewares.py", line 23, in dispatch
    |     response = await call_next(request)
    |                ^^^^^^^^^^^^^^^^^^^^^^^^
    |   File "C:\Users\Keila\AppData\Local\Programs\Python\Python311\Lib\site-packages\starlette\middleware\base.py", line 154, in call_next
    |     raise app_exc
    |   File "C:\Users\Keila\AppData\Local\Programs\Python\Python311\Lib\site-packages\starlette\middleware\base.py", line 141, in coro
    |     await self.app(scope, receive_or_disconnect, send_no_error)
    |   File "C:\Users\Keila\AppData\Local\Programs\Python\Python311\Lib\site-packages\starlette\middleware\base.py", line 177, in __call__
    |     with recv_stream, send_stream, collapse_excgroups():
    |   File "C:\Users\Keila\AppData\Local\Programs\Python\Python311\Lib\contextlib.py", line 155, in __exit__
    |     self.gen.throw(typ, value, traceback)
    |   File "C:\Users\Keila\AppData\Local\Programs\Python\Python311\Lib\site-packages\starlette\_utils.py", line 82, in collapse_excgroups
    |     raise exc
    |   File "C:\Users\Keila\AppData\Local\Programs\Python\Python311\Lib\site-packages\starlette\middleware\base.py", line 179, in __call__
    |     response = await self.dispatch_func(request, call_next)
    |                ^^^^^^^^^^^^^^^^^^^^^^^^^^^^^^^^^^^^^^^^^^^^
    |   File "C:\Users\Keila\AppData\Local\Programs\Python\Python311\Lib\site-packages\nicegui\middlewares.py", line 13, in dispatch
    |     response = await call_next(request)
    |                ^^^^^^^^^^^^^^^^^^^^^^^^
    |   File "C:\Users\Keila\AppData\Local\Programs\Python\Python311\Lib\site-packages\starlette\middleware\base.py", line 154, in call_next
    |     raise app_exc
    |   File "C:\Users\Keila\AppData\Local\Programs\Python\Python311\Lib\site-packages\starlette\middleware\base.py", line 141, in coro
    |     await self.app(scope, receive_or_disconnect, send_no_error)
    |   File "C:\Users\Keila\AppData\Local\Programs\Python\Python311\Lib\site-packages\starlette\middleware\gzip.py", line 20, in __call__
    |     await responder(scope, receive, send)
    |   File "C:\Users\Keila\AppData\Local\Programs\Python\Python311\Lib\site-packages\starlette\middleware\gzip.py", line 39, in __call__
    |     await self.app(scope, receive, self.send_with_gzip)
    |   File "C:\Users\Keila\AppData\Local\Programs\Python\Python311\Lib\site-packages\starlette\middleware\exceptions.py", line 62, in __call__
    |     await wrap_app_handling_exceptions(self.app, conn)(scope, receive, send)
    |   File "C:\Users\Keila\AppData\Local\Programs\Python\Python311\Lib\site-packages\starlette\_exception_handler.py", line 53, in wrapped_app
    |     raise exc
    |   File "C:\Users\Keila\AppData\Local\Programs\Python\Python311\Lib\site-packages\starlette\_exception_handler.py", line 42, in wrapped_app
    |     await app(scope, receive, sender)
    |   File "C:\Users\Keila\AppData\Local\Programs\Python\Python311\Lib\site-packages\starlette\routing.py", line 715, in __call__
    |     await self.middleware_stack(scope, receive, send)
    |   File "C:\Users\Keila\AppData\Local\Programs\Python\Python311\Lib\site-packages\starlette\routing.py", line 735, in app
    |     await route.handle(scope, receive, send)
    |   File "C:\Users\Keila\AppData\Local\Programs\Python\Python311\Lib\site-packages\starlette\routing.py", line 288, in handle
    |     await self.app(scope, receive, send)
    |   File "C:\Users\Keila\AppData\Local\Programs\Python\Python311\Lib\site-packages\starlette\routing.py", line 76, in app
    |     await wrap_app_handling_exceptions(app, request)(scope, receive, send)
    |   File "C:\Users\Keila\AppData\Local\Programs\Python\Python311\Lib\site-packages\starlette\_exception_handler.py", line 53, in wrapped_app
    |     raise exc
    |   File "C:\Users\Keila\AppData\Local\Programs\Python\Python311\Lib\site-packages\starlette\_exception_handler.py", line 42, in wrapped_app
    |     await app(scope, receive, sender)
    |   File "C:\Users\Keila\AppData\Local\Programs\Python\Python311\Lib\site-packages\starlette\routing.py", line 73, in app
    |     response = await f(request)
    |                ^^^^^^^^^^^^^^^^
    |   File "C:\Users\Keila\AppData\Local\Programs\Python\Python311\Lib\site-packages\fastapi\routing.py", line 301, in app
    |     raw_response = await run_endpoint_function(
    |                    ^^^^^^^^^^^^^^^^^^^^^^^^^^^^
    |   File "C:\Users\Keila\AppData\Local\Programs\Python\Python311\Lib\site-packages\fastapi\routing.py", line 212, in run_endpoint_function
    |     return await dependant.call(**values)
    |            ^^^^^^^^^^^^^^^^^^^^^^^^^^^^^^
    |   File "C:\Users\Keila\AppData\Local\Programs\Python\Python311\Lib\site-packages\nicegui\page.py", line 153, in decorated
    |     return create_error_page(e, request)
    |            ^^^^^^^^^^^^^^^^^^^^^^^^^^^^^
    |   File "C:\Users\Keila\AppData\Local\Programs\Python\Python311\Lib\site-packages\nicegui\page.py", line 116, in create_error_page
    |     raise e
    |   File "C:\Users\Keila\AppData\Local\Programs\Python\Python311\Lib\site-packages\nicegui\page.py", line 147, in decorated
    |     result = func(*dec_args, **dec_kwargs)
    |              ^^^^^^^^^^^^^^^^^^^^^^^^^^^^^
    |   File "c:\Users\Keila\Downloads\VehicleMax-main (1)\VehicleMax-main\VIN_Decoder\VIN-Decoder.py", line 29, in vin_decoder_page
    |     for url in app.urls:
    |                ^^^
    | NameError: name 'app' is not defined
    +------------------------------------

During handling of the above exception, another exception occurred:

Traceback (most recent call last):
  File "C:\Users\Keila\AppData\Local\Programs\Python\Python311\Lib\site-packages\starlette\middleware\errors.py", line 165, in __call__
    await self.app(scope, receive, _send)
  File "C:\Users\Keila\AppData\Local\Programs\Python\Python311\Lib\site-packages\starlette\middleware\base.py", line 177, in __call__
    with recv_stream, send_stream, collapse_excgroups():
  File "C:\Users\Keila\AppData\Local\Programs\Python\Python311\Lib\contextlib.py", line 155, in __exit__
    self.gen.throw(typ, value, traceback)
  File "C:\Users\Keila\AppData\Local\Programs\Python\Python311\Lib\site-packages\starlette\_utils.py", line 82, in collapse_excgroups
    raise exc
  File "C:\Users\Keila\AppData\Local\Programs\Python\Python311\Lib\site-packages\starlette\middleware\base.py", line 179, in __call__
    response = await self.dispatch_func(request, call_next)
               ^^^^^^^^^^^^^^^^^^^^^^^^^^^^^^^^^^^^^^^^^^^^
  File "C:\Users\Keila\AppData\Local\Programs\Python\Python311\Lib\site-packages\nicegui\middlewares.py", line 23, in dispatch
    response = await call_next(request)
               ^^^^^^^^^^^^^^^^^^^^^^^^
  File "C:\Users\Keila\AppData\Local\Programs\Python\Python311\Lib\site-packages\starlette\middleware\base.py", line 154, in call_next
    raise app_exc
  File "C:\Users\Keila\AppData\Local\Programs\Python\Python311\Lib\site-packages\starlette\middleware\base.py", line 141, in coro
    await self.app(scope, receive_or_disconnect, send_no_error)
  File "C:\Users\Keila\AppData\Local\Programs\Python\Python311\Lib\site-packages\starlette\middleware\base.py", line 177, in __call__
    with recv_stream, send_stream, collapse_excgroups():
  File "C:\Users\Keila\AppData\Local\Programs\Python\Python311\Lib\contextlib.py", line 155, in __exit__
    self.gen.throw(typ, value, traceback)
  File "C:\Users\Keila\AppData\Local\Programs\Python\Python311\Lib\site-packages\starlette\_utils.py", line 82, in collapse_excgroups
    raise exc
  File "C:\Users\Keila\AppData\Local\Programs\Python\Python311\Lib\site-packages\starlette\middleware\base.py", line 179, in __call__
    response = await self.dispatch_func(request, call_next)
               ^^^^^^^^^^^^^^^^^^^^^^^^^^^^^^^^^^^^^^^^^^^^
  File "C:\Users\Keila\AppData\Local\Programs\Python\Python311\Lib\site-packages\nicegui\middlewares.py", line 13, in dispatch
    response = await call_next(request)
               ^^^^^^^^^^^^^^^^^^^^^^^^
  File "C:\Users\Keila\AppData\Local\Programs\Python\Python311\Lib\site-packages\starlette\middleware\base.py", line 154, in call_next
    raise app_exc
  File "C:\Users\Keila\AppData\Local\Programs\Python\Python311\Lib\site-packages\starlette\middleware\base.py", line 141, in coro
    await self.app(scope, receive_or_disconnect, send_no_error)
  File "C:\Users\Keila\AppData\Local\Programs\Python\Python311\Lib\site-packages\starlette\middleware\gzip.py", line 20, in __call__
    await responder(scope, receive, send)
  File "C:\Users\Keila\AppData\Local\Programs\Python\Python311\Lib\site-packages\starlette\middleware\gzip.py", line 39, in __call__
    await self.app(scope, receive, self.send_with_gzip)
  File "C:\Users\Keila\AppData\Local\Programs\Python\Python311\Lib\site-packages\starlette\middleware\exceptions.py", line 62, in __call__
    await wrap_app_handling_exceptions(self.app, conn)(scope, receive, send)
  File "C:\Users\Keila\AppData\Local\Programs\Python\Python311\Lib\site-packages\starlette\_exception_handler.py", line 53, in wrapped_app
    raise exc
  File "C:\Users\Keila\AppData\Local\Programs\Python\Python311\Lib\site-packages\starlette\_exception_handler.py", line 42, in wrapped_app
    await app(scope, receive, sender)
  File "C:\Users\Keila\AppData\Local\Programs\Python\Python311\Lib\site-packages\starlette\routing.py", line 715, in __call__
    await self.middleware_stack(scope, receive, send)
  File "C:\Users\Keila\AppData\Local\Programs\Python\Python311\Lib\site-packages\starlette\routing.py", line 735, in app
    await route.handle(scope, receive, send)
  File "C:\Users\Keila\AppData\Local\Programs\Python\Python311\Lib\site-packages\starlette\routing.py", line 288, in handle
    await self.app(scope, receive, send)
  File "C:\Users\Keila\AppData\Local\Programs\Python\Python311\Lib\site-packages\starlette\routing.py", line 76, in app
    await wrap_app_handling_exceptions(app, request)(scope, receive, send)
  File "C:\Users\Keila\AppData\Local\Programs\Python\Python311\Lib\site-packages\starlette\_exception_handler.py", line 53, in wrapped_app
    raise exc
  File "C:\Users\Keila\AppData\Local\Programs\Python\Python311\Lib\site-packages\starlette\_exception_handler.py", line 42, in wrapped_app
    await app(scope, receive, sender)
  File "C:\Users\Keila\AppData\Local\Programs\Python\Python311\Lib\site-packages\starlette\routing.py", line 73, in app
    response = await f(request)
               ^^^^^^^^^^^^^^^^
  File "C:\Users\Keila\AppData\Local\Programs\Python\Python311\Lib\site-packages\fastapi\routing.py", line 301, in app
    raw_response = await run_endpoint_function(
                   ^^^^^^^^^^^^^^^^^^^^^^^^^^^^
  File "C:\Users\Keila\AppData\Local\Programs\Python\Python311\Lib\site-packages\fastapi\routing.py", line 212, in run_endpoint_function
    return await dependant.call(**values)
           ^^^^^^^^^^^^^^^^^^^^^^^^^^^^^^
  File "C:\Users\Keila\AppData\Local\Programs\Python\Python311\Lib\site-packages\nicegui\page.py", line 153, in decorated
    return create_error_page(e, request)
           ^^^^^^^^^^^^^^^^^^^^^^^^^^^^^
  File "C:\Users\Keila\AppData\Local\Programs\Python\Python311\Lib\site-packages\nicegui\page.py", line 116, in create_error_page
    raise e
  File "C:\Users\Keila\AppData\Local\Programs\Python\Python311\Lib\site-packages\nicegui\page.py", line 147, in decorated
    result = func(*dec_args, **dec_kwargs)
             ^^^^^^^^^^^^^^^^^^^^^^^^^^^^^
  File "c:\Users\Keila\Downloads\VehicleMax-main (1)\VehicleMax-main\VIN_Decoder\VIN-Decoder.py", line 29, in vin_decoder_page
    for url in app.urls:
               ^^^
NameError: name 'app' is not defined
ERROR:nicegui:name 'app' is not defined
  + Exception Group Traceback (most recent call last):
  |   File "C:\Users\Keila\AppData\Local\Programs\Python\Python311\Lib\site-packages\starlette\_utils.py", line 76, in collapse_excgroups
  |     yield
  |   File "C:\Users\Keila\AppData\Local\Programs\Python\Python311\Lib\site-packages\starlette\middleware\base.py", line 178, in __call__
  |     async with anyio.create_task_group() as task_group:
  |   File "C:\Users\Keila\AppData\Local\Programs\Python\Python311\Lib\site-packages\anyio\_backends\_asyncio.py", line 767, in __aexit__
  |     raise BaseExceptionGroup(
  | ExceptionGroup: unhandled errors in a TaskGroup (1 sub-exception)
  +-+---------------- 1 ----------------
    | Traceback (most recent call last):
    |   File "C:\Users\Keila\AppData\Local\Programs\Python\Python311\Lib\site-packages\starlette\middleware\errors.py", line 165, in __call__
    |     await self.app(scope, receive, _send)
    |   File "C:\Users\Keila\AppData\Local\Programs\Python\Python311\Lib\site-packages\starlette\middleware\base.py", line 177, in __call__
    |     with recv_stream, send_stream, collapse_excgroups():
    |   File "C:\Users\Keila\AppData\Local\Programs\Python\Python311\Lib\contextlib.py", line 155, in __exit__
    |     self.gen.throw(typ, value, traceback)
    |   File "C:\Users\Keila\AppData\Local\Programs\Python\Python311\Lib\site-packages\starlette\_utils.py", line 82, in collapse_excgroups
    |     raise exc
    |   File "C:\Users\Keila\AppData\Local\Programs\Python\Python311\Lib\site-packages\starlette\middleware\base.py", line 179, in __call__
    |     response = await self.dispatch_func(request, call_next)
    |                ^^^^^^^^^^^^^^^^^^^^^^^^^^^^^^^^^^^^^^^^^^^^
    |   File "C:\Users\Keila\AppData\Local\Programs\Python\Python311\Lib\site-packages\nicegui\middlewares.py", line 23, in dispatch
    |     response = await call_next(request)
    |                ^^^^^^^^^^^^^^^^^^^^^^^^
    |   File "C:\Users\Keila\AppData\Local\Programs\Python\Python311\Lib\site-packages\starlette\middleware\base.py", line 154, in call_next
    |     raise app_exc
    |   File "C:\Users\Keila\AppData\Local\Programs\Python\Python311\Lib\site-packages\starlette\middleware\base.py", line 141, in coro
    |     await self.app(scope, receive_or_disconnect, send_no_error)
    |   File "C:\Users\Keila\AppData\Local\Programs\Python\Python311\Lib\site-packages\starlette\middleware\base.py", line 177, in __call__
    |     with recv_stream, send_stream, collapse_excgroups():
    |   File "C:\Users\Keila\AppData\Local\Programs\Python\Python311\Lib\contextlib.py", line 155, in __exit__
    |     self.gen.throw(typ, value, traceback)
    |   File "C:\Users\Keila\AppData\Local\Programs\Python\Python311\Lib\site-packages\starlette\_utils.py", line 82, in collapse_excgroups
    |     raise exc
    |   File "C:\Users\Keila\AppData\Local\Programs\Python\Python311\Lib\site-packages\starlette\middleware\base.py", line 179, in __call__
    |     response = await self.dispatch_func(request, call_next)
    |                ^^^^^^^^^^^^^^^^^^^^^^^^^^^^^^^^^^^^^^^^^^^^
    |   File "C:\Users\Keila\AppData\Local\Programs\Python\Python311\Lib\site-packages\nicegui\middlewares.py", line 13, in dispatch
    |     response = await call_next(request)
    |                ^^^^^^^^^^^^^^^^^^^^^^^^
    |   File "C:\Users\Keila\AppData\Local\Programs\Python\Python311\Lib\site-packages\starlette\middleware\base.py", line 154, in call_next
    |     raise app_exc
    |   File "C:\Users\Keila\AppData\Local\Programs\Python\Python311\Lib\site-packages\starlette\middleware\base.py", line 141, in coro
    |     await self.app(scope, receive_or_disconnect, send_no_error)
    |   File "C:\Users\Keila\AppData\Local\Programs\Python\Python311\Lib\site-packages\starlette\middleware\gzip.py", line 20, in __call__
    |     await responder(scope, receive, send)
    |   File "C:\Users\Keila\AppData\Local\Programs\Python\Python311\Lib\site-packages\starlette\middleware\gzip.py", line 39, in __call__
    |     await self.app(scope, receive, self.send_with_gzip)
    |   File "C:\Users\Keila\AppData\Local\Programs\Python\Python311\Lib\site-packages\starlette\middleware\exceptions.py", line 62, in __call__
    |     await wrap_app_handling_exceptions(self.app, conn)(scope, receive, send)
    |   File "C:\Users\Keila\AppData\Local\Programs\Python\Python311\Lib\site-packages\starlette\_exception_handler.py", line 53, in wrapped_app
    |     raise exc
    |   File "C:\Users\Keila\AppData\Local\Programs\Python\Python311\Lib\site-packages\starlette\_exception_handler.py", line 42, in wrapped_app
    |     await app(scope, receive, sender)
    |   File "C:\Users\Keila\AppData\Local\Programs\Python\Python311\Lib\site-packages\starlette\routing.py", line 715, in __call__
    |     await self.middleware_stack(scope, receive, send)
    |   File "C:\Users\Keila\AppData\Local\Programs\Python\Python311\Lib\site-packages\starlette\routing.py", line 735, in app
    |     await route.handle(scope, receive, send)
    |   File "C:\Users\Keila\AppData\Local\Programs\Python\Python311\Lib\site-packages\starlette\routing.py", line 288, in handle
    |     await self.app(scope, receive, send)
    |   File "C:\Users\Keila\AppData\Local\Programs\Python\Python311\Lib\site-packages\starlette\routing.py", line 76, in app
    |     await wrap_app_handling_exceptions(app, request)(scope, receive, send)
    |   File "C:\Users\Keila\AppData\Local\Programs\Python\Python311\Lib\site-packages\starlette\_exception_handler.py", line 53, in wrapped_app
    |     raise exc
    |   File "C:\Users\Keila\AppData\Local\Programs\Python\Python311\Lib\site-packages\starlette\_exception_handler.py", line 42, in wrapped_app
    |     await app(scope, receive, sender)
    |   File "C:\Users\Keila\AppData\Local\Programs\Python\Python311\Lib\site-packages\starlette\routing.py", line 73, in app
    |     response = await f(request)
    |                ^^^^^^^^^^^^^^^^
    |   File "C:\Users\Keila\AppData\Local\Programs\Python\Python311\Lib\site-packages\fastapi\routing.py", line 301, in app
    |     raw_response = await run_endpoint_function(
    |                    ^^^^^^^^^^^^^^^^^^^^^^^^^^^^
    |   File "C:\Users\Keila\AppData\Local\Programs\Python\Python311\Lib\site-packages\fastapi\routing.py", line 212, in run_endpoint_function
    |     return await dependant.call(**values)
    |            ^^^^^^^^^^^^^^^^^^^^^^^^^^^^^^
    |   File "C:\Users\Keila\AppData\Local\Programs\Python\Python311\Lib\site-packages\nicegui\page.py", line 153, in decorated
    |     return create_error_page(e, request)
    |            ^^^^^^^^^^^^^^^^^^^^^^^^^^^^^
    |   File "C:\Users\Keila\AppData\Local\Programs\Python\Python311\Lib\site-packages\nicegui\page.py", line 116, in create_error_page
    |     raise e
    |   File "C:\Users\Keila\AppData\Local\Programs\Python\Python311\Lib\site-packages\nicegui\page.py", line 147, in decorated
    |     result = func(*dec_args, **dec_kwargs)
    |              ^^^^^^^^^^^^^^^^^^^^^^^^^^^^^
    |   File "c:\Users\Keila\Downloads\VehicleMax-main (1)\VehicleMax-main\VIN_Decoder\VIN-Decoder.py", line 29, in vin_decoder_page
    |     for url in app.urls:
    |                ^^^
    | NameError: name 'app' is not defined
    +------------------------------------

During handling of the above exception, another exception occurred:

Traceback (most recent call last):
  File "C:\Users\Keila\AppData\Local\Programs\Python\Python311\Lib\site-packages\starlette\middleware\errors.py", line 165, in __call__
    await self.app(scope, receive, _send)
  File "C:\Users\Keila\AppData\Local\Programs\Python\Python311\Lib\site-packages\starlette\middleware\base.py", line 177, in __call__
    with recv_stream, send_stream, collapse_excgroups():
  File "C:\Users\Keila\AppData\Local\Programs\Python\Python311\Lib\contextlib.py", line 155, in __exit__
    self.gen.throw(typ, value, traceback)
  File "C:\Users\Keila\AppData\Local\Programs\Python\Python311\Lib\site-packages\starlette\_utils.py", line 82, in collapse_excgroups
    raise exc
  File "C:\Users\Keila\AppData\Local\Programs\Python\Python311\Lib\site-packages\starlette\middleware\base.py", line 179, in __call__
    response = await self.dispatch_func(request, call_next)
               ^^^^^^^^^^^^^^^^^^^^^^^^^^^^^^^^^^^^^^^^^^^^
  File "C:\Users\Keila\AppData\Local\Programs\Python\Python311\Lib\site-packages\nicegui\middlewares.py", line 23, in dispatch
    response = await call_next(request)
               ^^^^^^^^^^^^^^^^^^^^^^^^
  File "C:\Users\Keila\AppData\Local\Programs\Python\Python311\Lib\site-packages\starlette\middleware\base.py", line 154, in call_next
    raise app_exc
  File "C:\Users\Keila\AppData\Local\Programs\Python\Python311\Lib\site-packages\starlette\middleware\base.py", line 141, in coro
    await self.app(scope, receive_or_disconnect, send_no_error)
  File "C:\Users\Keila\AppData\Local\Programs\Python\Python311\Lib\site-packages\starlette\middleware\base.py", line 177, in __call__
    with recv_stream, send_stream, collapse_excgroups():
  File "C:\Users\Keila\AppData\Local\Programs\Python\Python311\Lib\contextlib.py", line 155, in __exit__
    self.gen.throw(typ, value, traceback)
  File "C:\Users\Keila\AppData\Local\Programs\Python\Python311\Lib\site-packages\starlette\_utils.py", line 82, in collapse_excgroups
    raise exc
  File "C:\Users\Keila\AppData\Local\Programs\Python\Python311\Lib\site-packages\starlette\middleware\base.py", line 179, in __call__
    response = await self.dispatch_func(request, call_next)
               ^^^^^^^^^^^^^^^^^^^^^^^^^^^^^^^^^^^^^^^^^^^^
  File "C:\Users\Keila\AppData\Local\Programs\Python\Python311\Lib\site-packages\nicegui\middlewares.py", line 13, in dispatch
    response = await call_next(request)
               ^^^^^^^^^^^^^^^^^^^^^^^^
  File "C:\Users\Keila\AppData\Local\Programs\Python\Python311\Lib\site-packages\starlette\middleware\base.py", line 154, in call_next
    raise app_exc
  File "C:\Users\Keila\AppData\Local\Programs\Python\Python311\Lib\site-packages\starlette\middleware\base.py", line 141, in coro
    await self.app(scope, receive_or_disconnect, send_no_error)
  File "C:\Users\Keila\AppData\Local\Programs\Python\Python311\Lib\site-packages\starlette\middleware\gzip.py", line 20, in __call__
    await responder(scope, receive, send)
  File "C:\Users\Keila\AppData\Local\Programs\Python\Python311\Lib\site-packages\starlette\middleware\gzip.py", line 39, in __call__
    await self.app(scope, receive, self.send_with_gzip)
  File "C:\Users\Keila\AppData\Local\Programs\Python\Python311\Lib\site-packages\starlette\middleware\exceptions.py", line 62, in __call__
    await wrap_app_handling_exceptions(self.app, conn)(scope, receive, send)
  File "C:\Users\Keila\AppData\Local\Programs\Python\Python311\Lib\site-packages\starlette\_exception_handler.py", line 53, in wrapped_app
    raise exc
  File "C:\Users\Keila\AppData\Local\Programs\Python\Python311\Lib\site-packages\starlette\_exception_handler.py", line 42, in wrapped_app
    await app(scope, receive, sender)
  File "C:\Users\Keila\AppData\Local\Programs\Python\Python311\Lib\site-packages\starlette\routing.py", line 715, in __call__
    await self.middleware_stack(scope, receive, send)
  File "C:\Users\Keila\AppData\Local\Programs\Python\Python311\Lib\site-packages\starlette\routing.py", line 735, in app
    await route.handle(scope, receive, send)
  File "C:\Users\Keila\AppData\Local\Programs\Python\Python311\Lib\site-packages\starlette\routing.py", line 288, in handle
    await self.app(scope, receive, send)
  File "C:\Users\Keila\AppData\Local\Programs\Python\Python311\Lib\site-packages\starlette\routing.py", line 76, in app
    await wrap_app_handling_exceptions(app, request)(scope, receive, send)
  File "C:\Users\Keila\AppData\Local\Programs\Python\Python311\Lib\site-packages\starlette\_exception_handler.py", line 53, in wrapped_app
    raise exc
  File "C:\Users\Keila\AppData\Local\Programs\Python\Python311\Lib\site-packages\starlette\_exception_handler.py", line 42, in wrapped_app
    await app(scope, receive, sender)
  File "C:\Users\Keila\AppData\Local\Programs\Python\Python311\Lib\site-packages\starlette\routing.py", line 73, in app
    response = await f(request)
               ^^^^^^^^^^^^^^^^
  File "C:\Users\Keila\AppData\Local\Programs\Python\Python311\Lib\site-packages\fastapi\routing.py", line 301, in app
    raw_response = await run_endpoint_function(
                   ^^^^^^^^^^^^^^^^^^^^^^^^^^^^
  File "C:\Users\Keila\AppData\Local\Programs\Python\Python311\Lib\site-packages\fastapi\routing.py", line 212, in run_endpoint_function
    return await dependant.call(**values)
           ^^^^^^^^^^^^^^^^^^^^^^^^^^^^^^
  File "C:\Users\Keila\AppData\Local\Programs\Python\Python311\Lib\site-packages\nicegui\page.py", line 153, in decorated
    return create_error_page(e, request)
           ^^^^^^^^^^^^^^^^^^^^^^^^^^^^^
  File "C:\Users\Keila\AppData\Local\Programs\Python\Python311\Lib\site-packages\nicegui\page.py", line 116, in create_error_page
    raise e
  File "C:\Users\Keila\AppData\Local\Programs\Python\Python311\Lib\site-packages\nicegui\page.py", line 147, in decorated
    result = func(*dec_args, **dec_kwargs)
             ^^^^^^^^^^^^^^^^^^^^^^^^^^^^^
  File "c:\Users\Keila\Downloads\VehicleMax-main (1)\VehicleMax-main\VIN_Decoder\VIN-Decoder.py", line 29, in vin_decoder_page
    for url in app.urls:
               ^^^
NameError: name 'app' is not defined
ERROR:nicegui:name 'app' is not defined
  + Exception Group Traceback (most recent call last):
  |   File "C:\Users\Keila\AppData\Local\Programs\Python\Python311\Lib\site-packages\starlette\_utils.py", line 76, in collapse_excgroups
  |     yield
  |   File "C:\Users\Keila\AppData\Local\Programs\Python\Python311\Lib\site-packages\starlette\middleware\base.py", line 178, in __call__
  |     async with anyio.create_task_group() as task_group:
  |   File "C:\Users\Keila\AppData\Local\Programs\Python\Python311\Lib\site-packages\anyio\_backends\_asyncio.py", line 767, in __aexit__
  |     raise BaseExceptionGroup(
  | ExceptionGroup: unhandled errors in a TaskGroup (1 sub-exception)
  +-+---------------- 1 ----------------
    | Traceback (most recent call last):
    |   File "C:\Users\Keila\AppData\Local\Programs\Python\Python311\Lib\site-packages\starlette\middleware\errors.py", line 165, in __call__
    |     await self.app(scope, receive, _send)
    |   File "C:\Users\Keila\AppData\Local\Programs\Python\Python311\Lib\site-packages\starlette\middleware\base.py", line 177, in __call__
    |     with recv_stream, send_stream, collapse_excgroups():
    |   File "C:\Users\Keila\AppData\Local\Programs\Python\Python311\Lib\contextlib.py", line 155, in __exit__
    |     self.gen.throw(typ, value, traceback)
    |   File "C:\Users\Keila\AppData\Local\Programs\Python\Python311\Lib\site-packages\starlette\_utils.py", line 82, in collapse_excgroups
    |     raise exc
    |   File "C:\Users\Keila\AppData\Local\Programs\Python\Python311\Lib\site-packages\starlette\middleware\base.py", line 179, in __call__
    |     response = await self.dispatch_func(request, call_next)
    |                ^^^^^^^^^^^^^^^^^^^^^^^^^^^^^^^^^^^^^^^^^^^^
    |   File "C:\Users\Keila\AppData\Local\Programs\Python\Python311\Lib\site-packages\nicegui\middlewares.py", line 23, in dispatch
    |     response = await call_next(request)
    |                ^^^^^^^^^^^^^^^^^^^^^^^^
    |   File "C:\Users\Keila\AppData\Local\Programs\Python\Python311\Lib\site-packages\starlette\middleware\base.py", line 154, in call_next
    |     raise app_exc
    |   File "C:\Users\Keila\AppData\Local\Programs\Python\Python311\Lib\site-packages\starlette\middleware\base.py", line 141, in coro
    |     await self.app(scope, receive_or_disconnect, send_no_error)
    |   File "C:\Users\Keila\AppData\Local\Programs\Python\Python311\Lib\site-packages\starlette\middleware\base.py", line 177, in __call__
    |     with recv_stream, send_stream, collapse_excgroups():
    |   File "C:\Users\Keila\AppData\Local\Programs\Python\Python311\Lib\contextlib.py", line 155, in __exit__
    |     self.gen.throw(typ, value, traceback)
    |   File "C:\Users\Keila\AppData\Local\Programs\Python\Python311\Lib\site-packages\starlette\_utils.py", line 82, in collapse_excgroups
    |     raise exc
    |   File "C:\Users\Keila\AppData\Local\Programs\Python\Python311\Lib\site-packages\starlette\middleware\base.py", line 179, in __call__
    |     response = await self.dispatch_func(request, call_next)
    |                ^^^^^^^^^^^^^^^^^^^^^^^^^^^^^^^^^^^^^^^^^^^^
    |   File "C:\Users\Keila\AppData\Local\Programs\Python\Python311\Lib\site-packages\nicegui\middlewares.py", line 13, in dispatch
    |     response = await call_next(request)
    |                ^^^^^^^^^^^^^^^^^^^^^^^^
    |   File "C:\Users\Keila\AppData\Local\Programs\Python\Python311\Lib\site-packages\starlette\middleware\base.py", line 154, in call_next
    |     raise app_exc
    |   File "C:\Users\Keila\AppData\Local\Programs\Python\Python311\Lib\site-packages\starlette\middleware\base.py", line 141, in coro
    |     await self.app(scope, receive_or_disconnect, send_no_error)
    |   File "C:\Users\Keila\AppData\Local\Programs\Python\Python311\Lib\site-packages\starlette\middleware\gzip.py", line 20, in __call__
    |     await responder(scope, receive, send)
    |   File "C:\Users\Keila\AppData\Local\Programs\Python\Python311\Lib\site-packages\starlette\middleware\gzip.py", line 39, in __call__
    |     await self.app(scope, receive, self.send_with_gzip)
    |   File "C:\Users\Keila\AppData\Local\Programs\Python\Python311\Lib\site-packages\starlette\middleware\exceptions.py", line 62, in __call__
    |     await wrap_app_handling_exceptions(self.app, conn)(scope, receive, send)
    |   File "C:\Users\Keila\AppData\Local\Programs\Python\Python311\Lib\site-packages\starlette\_exception_handler.py", line 53, in wrapped_app
    |     raise exc
    |   File "C:\Users\Keila\AppData\Local\Programs\Python\Python311\Lib\site-packages\starlette\_exception_handler.py", line 42, in wrapped_app
    |     await app(scope, receive, sender)
    |   File "C:\Users\Keila\AppData\Local\Programs\Python\Python311\Lib\site-packages\starlette\routing.py", line 715, in __call__
    |     await self.middleware_stack(scope, receive, send)
    |   File "C:\Users\Keila\AppData\Local\Programs\Python\Python311\Lib\site-packages\starlette\routing.py", line 735, in app
    |     await route.handle(scope, receive, send)
    |   File "C:\Users\Keila\AppData\Local\Programs\Python\Python311\Lib\site-packages\starlette\routing.py", line 288, in handle
    |     await self.app(scope, receive, send)
    |   File "C:\Users\Keila\AppData\Local\Programs\Python\Python311\Lib\site-packages\starlette\routing.py", line 76, in app
    |     await wrap_app_handling_exceptions(app, request)(scope, receive, send)
    |   File "C:\Users\Keila\AppData\Local\Programs\Python\Python311\Lib\site-packages\starlette\_exception_handler.py", line 53, in wrapped_app
    |     raise exc
    |   File "C:\Users\Keila\AppData\Local\Programs\Python\Python311\Lib\site-packages\starlette\_exception_handler.py", line 42, in wrapped_app
    |     await app(scope, receive, sender)
    |   File "C:\Users\Keila\AppData\Local\Programs\Python\Python311\Lib\site-packages\starlette\routing.py", line 73, in app
    |     response = await f(request)
    |                ^^^^^^^^^^^^^^^^
    |   File "C:\Users\Keila\AppData\Local\Programs\Python\Python311\Lib\site-packages\fastapi\routing.py", line 301, in app
    |     raw_response = await run_endpoint_function(
    |                    ^^^^^^^^^^^^^^^^^^^^^^^^^^^^
    |   File "C:\Users\Keila\AppData\Local\Programs\Python\Python311\Lib\site-packages\fastapi\routing.py", line 212, in run_endpoint_function
    |     return await dependant.call(**values)
    |            ^^^^^^^^^^^^^^^^^^^^^^^^^^^^^^
    |   File "C:\Users\Keila\AppData\Local\Programs\Python\Python311\Lib\site-packages\nicegui\page.py", line 153, in decorated
    |     return create_error_page(e, request)
    |            ^^^^^^^^^^^^^^^^^^^^^^^^^^^^^
    |   File "C:\Users\Keila\AppData\Local\Programs\Python\Python311\Lib\site-packages\nicegui\page.py", line 116, in create_error_page
    |     raise e
    |   File "C:\Users\Keila\AppData\Local\Programs\Python\Python311\Lib\site-packages\nicegui\page.py", line 147, in decorated
    |     result = func(*dec_args, **dec_kwargs)
    |              ^^^^^^^^^^^^^^^^^^^^^^^^^^^^^
    |   File "c:\Users\Keila\Downloads\VehicleMax-main (1)\VehicleMax-main\VIN_Decoder\VIN-Decoder.py", line 29, in vin_decoder_page
    |     for url in app.urls:
    |                ^^^
    | NameError: name 'app' is not defined
    +------------------------------------

During handling of the above exception, another exception occurred:

Traceback (most recent call last):
  File "C:\Users\Keila\AppData\Local\Programs\Python\Python311\Lib\site-packages\starlette\middleware\errors.py", line 165, in __call__
    await self.app(scope, receive, _send)
  File "C:\Users\Keila\AppData\Local\Programs\Python\Python311\Lib\site-packages\starlette\middleware\base.py", line 177, in __call__
    with recv_stream, send_stream, collapse_excgroups():
  File "C:\Users\Keila\AppData\Local\Programs\Python\Python311\Lib\contextlib.py", line 155, in __exit__
    self.gen.throw(typ, value, traceback)
  File "C:\Users\Keila\AppData\Local\Programs\Python\Python311\Lib\site-packages\starlette\_utils.py", line 82, in collapse_excgroups
    raise exc
  File "C:\Users\Keila\AppData\Local\Programs\Python\Python311\Lib\site-packages\starlette\middleware\base.py", line 179, in __call__
    response = await self.dispatch_func(request, call_next)
               ^^^^^^^^^^^^^^^^^^^^^^^^^^^^^^^^^^^^^^^^^^^^
  File "C:\Users\Keila\AppData\Local\Programs\Python\Python311\Lib\site-packages\nicegui\middlewares.py", line 23, in dispatch
    response = await call_next(request)
               ^^^^^^^^^^^^^^^^^^^^^^^^
  File "C:\Users\Keila\AppData\Local\Programs\Python\Python311\Lib\site-packages\starlette\middleware\base.py", line 154, in call_next
    raise app_exc
  File "C:\Users\Keila\AppData\Local\Programs\Python\Python311\Lib\site-packages\starlette\middleware\base.py", line 141, in coro
    await self.app(scope, receive_or_disconnect, send_no_error)
  File "C:\Users\Keila\AppData\Local\Programs\Python\Python311\Lib\site-packages\starlette\middleware\base.py", line 177, in __call__
    with recv_stream, send_stream, collapse_excgroups():
  File "C:\Users\Keila\AppData\Local\Programs\Python\Python311\Lib\contextlib.py", line 155, in __exit__
    self.gen.throw(typ, value, traceback)
  File "C:\Users\Keila\AppData\Local\Programs\Python\Python311\Lib\site-packages\starlette\_utils.py", line 82, in collapse_excgroups
    raise exc
  File "C:\Users\Keila\AppData\Local\Programs\Python\Python311\Lib\site-packages\starlette\middleware\base.py", line 179, in __call__
    response = await self.dispatch_func(request, call_next)
               ^^^^^^^^^^^^^^^^^^^^^^^^^^^^^^^^^^^^^^^^^^^^
  File "C:\Users\Keila\AppData\Local\Programs\Python\Python311\Lib\site-packages\nicegui\middlewares.py", line 13, in dispatch
    response = await call_next(request)
               ^^^^^^^^^^^^^^^^^^^^^^^^
  File "C:\Users\Keila\AppData\Local\Programs\Python\Python311\Lib\site-packages\starlette\middleware\base.py", line 154, in call_next
    raise app_exc
  File "C:\Users\Keila\AppData\Local\Programs\Python\Python311\Lib\site-packages\starlette\middleware\base.py", line 141, in coro
    await self.app(scope, receive_or_disconnect, send_no_error)
  File "C:\Users\Keila\AppData\Local\Programs\Python\Python311\Lib\site-packages\starlette\middleware\gzip.py", line 20, in __call__
    await responder(scope, receive, send)
  File "C:\Users\Keila\AppData\Local\Programs\Python\Python311\Lib\site-packages\starlette\middleware\gzip.py", line 39, in __call__
    await self.app(scope, receive, self.send_with_gzip)
  File "C:\Users\Keila\AppData\Local\Programs\Python\Python311\Lib\site-packages\starlette\middleware\exceptions.py", line 62, in __call__
    await wrap_app_handling_exceptions(self.app, conn)(scope, receive, send)
  File "C:\Users\Keila\AppData\Local\Programs\Python\Python311\Lib\site-packages\starlette\_exception_handler.py", line 53, in wrapped_app
    raise exc
  File "C:\Users\Keila\AppData\Local\Programs\Python\Python311\Lib\site-packages\starlette\_exception_handler.py", line 42, in wrapped_app
    await app(scope, receive, sender)
  File "C:\Users\Keila\AppData\Local\Programs\Python\Python311\Lib\site-packages\starlette\routing.py", line 715, in __call__
    await self.middleware_stack(scope, receive, send)
  File "C:\Users\Keila\AppData\Local\Programs\Python\Python311\Lib\site-packages\starlette\routing.py", line 735, in app
    await route.handle(scope, receive, send)
  File "C:\Users\Keila\AppData\Local\Programs\Python\Python311\Lib\site-packages\starlette\routing.py", line 288, in handle
    await self.app(scope, receive, send)
  File "C:\Users\Keila\AppData\Local\Programs\Python\Python311\Lib\site-packages\starlette\routing.py", line 76, in app
    await wrap_app_handling_exceptions(app, request)(scope, receive, send)
  File "C:\Users\Keila\AppData\Local\Programs\Python\Python311\Lib\site-packages\starlette\_exception_handler.py", line 53, in wrapped_app
    raise exc
  File "C:\Users\Keila\AppData\Local\Programs\Python\Python311\Lib\site-packages\starlette\_exception_handler.py", line 42, in wrapped_app
    await app(scope, receive, sender)
  File "C:\Users\Keila\AppData\Local\Programs\Python\Python311\Lib\site-packages\starlette\routing.py", line 73, in app
    response = await f(request)
               ^^^^^^^^^^^^^^^^
  File "C:\Users\Keila\AppData\Local\Programs\Python\Python311\Lib\site-packages\fastapi\routing.py", line 301, in app
    raw_response = await run_endpoint_function(
                   ^^^^^^^^^^^^^^^^^^^^^^^^^^^^
  File "C:\Users\Keila\AppData\Local\Programs\Python\Python311\Lib\site-packages\fastapi\routing.py", line 212, in run_endpoint_function
    return await dependant.call(**values)
           ^^^^^^^^^^^^^^^^^^^^^^^^^^^^^^
  File "C:\Users\Keila\AppData\Local\Programs\Python\Python311\Lib\site-packages\nicegui\page.py", line 153, in decorated
    return create_error_page(e, request)
           ^^^^^^^^^^^^^^^^^^^^^^^^^^^^^
  File "C:\Users\Keila\AppData\Local\Programs\Python\Python311\Lib\site-packages\nicegui\page.py", line 116, in create_error_page
    raise e
  File "C:\Users\Keila\AppData\Local\Programs\Python\Python311\Lib\site-packages\nicegui\page.py", line 147, in decorated
    result = func(*dec_args, **dec_kwargs)
             ^^^^^^^^^^^^^^^^^^^^^^^^^^^^^
  File "c:\Users\Keila\Downloads\VehicleMax-main (1)\VehicleMax-main\VIN_Decoder\VIN-Decoder.py", line 29, in vin_decoder_page
    for url in app.urls:
               ^^^
NameError: name 'app' is not defined
ERROR:nicegui:name 'app' is not defined
  + Exception Group Traceback (most recent call last):
  |   File "C:\Users\Keila\AppData\Local\Programs\Python\Python311\Lib\site-packages\starlette\_utils.py", line 76, in collapse_excgroups
  |     yield
  |   File "C:\Users\Keila\AppData\Local\Programs\Python\Python311\Lib\site-packages\starlette\middleware\base.py", line 178, in __call__
  |     async with anyio.create_task_group() as task_group:
  |   File "C:\Users\Keila\AppData\Local\Programs\Python\Python311\Lib\site-packages\anyio\_backends\_asyncio.py", line 767, in __aexit__
  |     raise BaseExceptionGroup(
  | ExceptionGroup: unhandled errors in a TaskGroup (1 sub-exception)
  +-+---------------- 1 ----------------
    | Traceback (most recent call last):
    |   File "C:\Users\Keila\AppData\Local\Programs\Python\Python311\Lib\site-packages\starlette\middleware\errors.py", line 165, in __call__
    |     await self.app(scope, receive, _send)
    |   File "C:\Users\Keila\AppData\Local\Programs\Python\Python311\Lib\site-packages\starlette\middleware\base.py", line 177, in __call__
    |     with recv_stream, send_stream, collapse_excgroups():
    |   File "C:\Users\Keila\AppData\Local\Programs\Python\Python311\Lib\contextlib.py", line 155, in __exit__
    |     self.gen.throw(typ, value, traceback)
    |   File "C:\Users\Keila\AppData\Local\Programs\Python\Python311\Lib\site-packages\starlette\_utils.py", line 82, in collapse_excgroups
    |     raise exc
    |   File "C:\Users\Keila\AppData\Local\Programs\Python\Python311\Lib\site-packages\starlette\middleware\base.py", line 179, in __call__
    |     response = await self.dispatch_func(request, call_next)
    |                ^^^^^^^^^^^^^^^^^^^^^^^^^^^^^^^^^^^^^^^^^^^^
    |   File "C:\Users\Keila\AppData\Local\Programs\Python\Python311\Lib\site-packages\nicegui\middlewares.py", line 23, in dispatch
    |     response = await call_next(request)
    |                ^^^^^^^^^^^^^^^^^^^^^^^^
    |   File "C:\Users\Keila\AppData\Local\Programs\Python\Python311\Lib\site-packages\starlette\middleware\base.py", line 154, in call_next
    |     raise app_exc
    |   File "C:\Users\Keila\AppData\Local\Programs\Python\Python311\Lib\site-packages\starlette\middleware\base.py", line 141, in coro
    |     await self.app(scope, receive_or_disconnect, send_no_error)
    |   File "C:\Users\Keila\AppData\Local\Programs\Python\Python311\Lib\site-packages\starlette\middleware\base.py", line 177, in __call__
    |     with recv_stream, send_stream, collapse_excgroups():
    |   File "C:\Users\Keila\AppData\Local\Programs\Python\Python311\Lib\contextlib.py", line 155, in __exit__
    |     self.gen.throw(typ, value, traceback)
    |   File "C:\Users\Keila\AppData\Local\Programs\Python\Python311\Lib\site-packages\starlette\_utils.py", line 82, in collapse_excgroups
    |     raise exc
    |   File "C:\Users\Keila\AppData\Local\Programs\Python\Python311\Lib\site-packages\starlette\middleware\base.py", line 179, in __call__
    |     response = await self.dispatch_func(request, call_next)
    |                ^^^^^^^^^^^^^^^^^^^^^^^^^^^^^^^^^^^^^^^^^^^^
    |   File "C:\Users\Keila\AppData\Local\Programs\Python\Python311\Lib\site-packages\nicegui\middlewares.py", line 13, in dispatch
    |     response = await call_next(request)
    |                ^^^^^^^^^^^^^^^^^^^^^^^^
    |   File "C:\Users\Keila\AppData\Local\Programs\Python\Python311\Lib\site-packages\starlette\middleware\base.py", line 154, in call_next
    |     raise app_exc
    |   File "C:\Users\Keila\AppData\Local\Programs\Python\Python311\Lib\site-packages\starlette\middleware\base.py", line 141, in coro
    |     await self.app(scope, receive_or_disconnect, send_no_error)
    |   File "C:\Users\Keila\AppData\Local\Programs\Python\Python311\Lib\site-packages\starlette\middleware\gzip.py", line 20, in __call__
    |     await responder(scope, receive, send)
    |   File "C:\Users\Keila\AppData\Local\Programs\Python\Python311\Lib\site-packages\starlette\middleware\gzip.py", line 39, in __call__
    |     await self.app(scope, receive, self.send_with_gzip)
    |   File "C:\Users\Keila\AppData\Local\Programs\Python\Python311\Lib\site-packages\starlette\middleware\exceptions.py", line 62, in __call__
    |     await wrap_app_handling_exceptions(self.app, conn)(scope, receive, send)
    |   File "C:\Users\Keila\AppData\Local\Programs\Python\Python311\Lib\site-packages\starlette\_exception_handler.py", line 53, in wrapped_app
    |     raise exc
    |   File "C:\Users\Keila\AppData\Local\Programs\Python\Python311\Lib\site-packages\starlette\_exception_handler.py", line 42, in wrapped_app
    |     await app(scope, receive, sender)
    |   File "C:\Users\Keila\AppData\Local\Programs\Python\Python311\Lib\site-packages\starlette\routing.py", line 715, in __call__
    |     await self.middleware_stack(scope, receive, send)
    |   File "C:\Users\Keila\AppData\Local\Programs\Python\Python311\Lib\site-packages\starlette\routing.py", line 735, in app
    |     await route.handle(scope, receive, send)
    |   File "C:\Users\Keila\AppData\Local\Programs\Python\Python311\Lib\site-packages\starlette\routing.py", line 288, in handle
    |     await self.app(scope, receive, send)
    |   File "C:\Users\Keila\AppData\Local\Programs\Python\Python311\Lib\site-packages\starlette\routing.py", line 76, in app
    |     await wrap_app_handling_exceptions(app, request)(scope, receive, send)
    |   File "C:\Users\Keila\AppData\Local\Programs\Python\Python311\Lib\site-packages\starlette\_exception_handler.py", line 53, in wrapped_app
    |     raise exc
    |   File "C:\Users\Keila\AppData\Local\Programs\Python\Python311\Lib\site-packages\starlette\_exception_handler.py", line 42, in wrapped_app
    |     await app(scope, receive, sender)
    |   File "C:\Users\Keila\AppData\Local\Programs\Python\Python311\Lib\site-packages\starlette\routing.py", line 73, in app
    |     response = await f(request)
    |                ^^^^^^^^^^^^^^^^
    |   File "C:\Users\Keila\AppData\Local\Programs\Python\Python311\Lib\site-packages\fastapi\routing.py", line 301, in app
    |     raw_response = await run_endpoint_function(
    |                    ^^^^^^^^^^^^^^^^^^^^^^^^^^^^
    |   File "C:\Users\Keila\AppData\Local\Programs\Python\Python311\Lib\site-packages\fastapi\routing.py", line 212, in run_endpoint_function
    |     return await dependant.call(**values)
    |            ^^^^^^^^^^^^^^^^^^^^^^^^^^^^^^
    |   File "C:\Users\Keila\AppData\Local\Programs\Python\Python311\Lib\site-packages\nicegui\page.py", line 153, in decorated
    |     return create_error_page(e, request)
    |            ^^^^^^^^^^^^^^^^^^^^^^^^^^^^^
    |   File "C:\Users\Keila\AppData\Local\Programs\Python\Python311\Lib\site-packages\nicegui\page.py", line 116, in create_error_page
    |     raise e
    |   File "C:\Users\Keila\AppData\Local\Programs\Python\Python311\Lib\site-packages\nicegui\page.py", line 147, in decorated
    |     result = func(*dec_args, **dec_kwargs)
    |              ^^^^^^^^^^^^^^^^^^^^^^^^^^^^^
    |   File "c:\Users\Keila\Downloads\VehicleMax-main (1)\VehicleMax-main\VIN_Decoder\VIN-Decoder.py", line 29, in vin_decoder_page
    |     for url in app.urls:
    |                ^^^
    | NameError: name 'app' is not defined
    +------------------------------------

During handling of the above exception, another exception occurred:

Traceback (most recent call last):
  File "C:\Users\Keila\AppData\Local\Programs\Python\Python311\Lib\site-packages\starlette\middleware\errors.py", line 165, in __call__
    await self.app(scope, receive, _send)
  File "C:\Users\Keila\AppData\Local\Programs\Python\Python311\Lib\site-packages\starlette\middleware\base.py", line 177, in __call__
    with recv_stream, send_stream, collapse_excgroups():
  File "C:\Users\Keila\AppData\Local\Programs\Python\Python311\Lib\contextlib.py", line 155, in __exit__
    self.gen.throw(typ, value, traceback)
  File "C:\Users\Keila\AppData\Local\Programs\Python\Python311\Lib\site-packages\starlette\_utils.py", line 82, in collapse_excgroups
    raise exc
  File "C:\Users\Keila\AppData\Local\Programs\Python\Python311\Lib\site-packages\starlette\middleware\base.py", line 179, in __call__
    response = await self.dispatch_func(request, call_next)
               ^^^^^^^^^^^^^^^^^^^^^^^^^^^^^^^^^^^^^^^^^^^^
  File "C:\Users\Keila\AppData\Local\Programs\Python\Python311\Lib\site-packages\nicegui\middlewares.py", line 23, in dispatch
    response = await call_next(request)
               ^^^^^^^^^^^^^^^^^^^^^^^^
  File "C:\Users\Keila\AppData\Local\Programs\Python\Python311\Lib\site-packages\starlette\middleware\base.py", line 154, in call_next
    raise app_exc
  File "C:\Users\Keila\AppData\Local\Programs\Python\Python311\Lib\site-packages\starlette\middleware\base.py", line 141, in coro
    await self.app(scope, receive_or_disconnect, send_no_error)
  File "C:\Users\Keila\AppData\Local\Programs\Python\Python311\Lib\site-packages\starlette\middleware\base.py", line 177, in __call__
    with recv_stream, send_stream, collapse_excgroups():
  File "C:\Users\Keila\AppData\Local\Programs\Python\Python311\Lib\contextlib.py", line 155, in __exit__
    self.gen.throw(typ, value, traceback)
  File "C:\Users\Keila\AppData\Local\Programs\Python\Python311\Lib\site-packages\starlette\_utils.py", line 82, in collapse_excgroups
    raise exc
  File "C:\Users\Keila\AppData\Local\Programs\Python\Python311\Lib\site-packages\starlette\middleware\base.py", line 179, in __call__
    response = await self.dispatch_func(request, call_next)
               ^^^^^^^^^^^^^^^^^^^^^^^^^^^^^^^^^^^^^^^^^^^^
  File "C:\Users\Keila\AppData\Local\Programs\Python\Python311\Lib\site-packages\nicegui\middlewares.py", line 13, in dispatch
    response = await call_next(request)
               ^^^^^^^^^^^^^^^^^^^^^^^^
  File "C:\Users\Keila\AppData\Local\Programs\Python\Python311\Lib\site-packages\starlette\middleware\base.py", line 154, in call_next
    raise app_exc
  File "C:\Users\Keila\AppData\Local\Programs\Python\Python311\Lib\site-packages\starlette\middleware\base.py", line 141, in coro
    await self.app(scope, receive_or_disconnect, send_no_error)
  File "C:\Users\Keila\AppData\Local\Programs\Python\Python311\Lib\site-packages\starlette\middleware\gzip.py", line 20, in __call__
    await responder(scope, receive, send)
  File "C:\Users\Keila\AppData\Local\Programs\Python\Python311\Lib\site-packages\starlette\middleware\gzip.py", line 39, in __call__
    await self.app(scope, receive, self.send_with_gzip)
  File "C:\Users\Keila\AppData\Local\Programs\Python\Python311\Lib\site-packages\starlette\middleware\exceptions.py", line 62, in __call__
    await wrap_app_handling_exceptions(self.app, conn)(scope, receive, send)
  File "C:\Users\Keila\AppData\Local\Programs\Python\Python311\Lib\site-packages\starlette\_exception_handler.py", line 53, in wrapped_app
    raise exc
  File "C:\Users\Keila\AppData\Local\Programs\Python\Python311\Lib\site-packages\starlette\_exception_handler.py", line 42, in wrapped_app
    await app(scope, receive, sender)
  File "C:\Users\Keila\AppData\Local\Programs\Python\Python311\Lib\site-packages\starlette\routing.py", line 715, in __call__
    await self.middleware_stack(scope, receive, send)
  File "C:\Users\Keila\AppData\Local\Programs\Python\Python311\Lib\site-packages\starlette\routing.py", line 735, in app
    await route.handle(scope, receive, send)
  File "C:\Users\Keila\AppData\Local\Programs\Python\Python311\Lib\site-packages\starlette\routing.py", line 288, in handle
    await self.app(scope, receive, send)
  File "C:\Users\Keila\AppData\Local\Programs\Python\Python311\Lib\site-packages\starlette\routing.py", line 76, in app
    await wrap_app_handling_exceptions(app, request)(scope, receive, send)
  File "C:\Users\Keila\AppData\Local\Programs\Python\Python311\Lib\site-packages\starlette\_exception_handler.py", line 53, in wrapped_app
    raise exc
  File "C:\Users\Keila\AppData\Local\Programs\Python\Python311\Lib\site-packages\starlette\_exception_handler.py", line 42, in wrapped_app
    await app(scope, receive, sender)
  File "C:\Users\Keila\AppData\Local\Programs\Python\Python311\Lib\site-packages\starlette\routing.py", line 73, in app
    response = await f(request)
               ^^^^^^^^^^^^^^^^
  File "C:\Users\Keila\AppData\Local\Programs\Python\Python311\Lib\site-packages\fastapi\routing.py", line 301, in app
    raw_response = await run_endpoint_function(
                   ^^^^^^^^^^^^^^^^^^^^^^^^^^^^
  File "C:\Users\Keila\AppData\Local\Programs\Python\Python311\Lib\site-packages\fastapi\routing.py", line 212, in run_endpoint_function
    return await dependant.call(**values)
           ^^^^^^^^^^^^^^^^^^^^^^^^^^^^^^
  File "C:\Users\Keila\AppData\Local\Programs\Python\Python311\Lib\site-packages\nicegui\page.py", line 153, in decorated
    return create_error_page(e, request)
           ^^^^^^^^^^^^^^^^^^^^^^^^^^^^^
  File "C:\Users\Keila\AppData\Local\Programs\Python\Python311\Lib\site-packages\nicegui\page.py", line 116, in create_error_page
    raise e
  File "C:\Users\Keila\AppData\Local\Programs\Python\Python311\Lib\site-packages\nicegui\page.py", line 147, in decorated
    result = func(*dec_args, **dec_kwargs)
             ^^^^^^^^^^^^^^^^^^^^^^^^^^^^^
  File "c:\Users\Keila\Downloads\VehicleMax-main (1)\VehicleMax-main\VIN_Decoder\VIN-Decoder.py", line 29, in vin_decoder_page
    for url in app.urls:
               ^^^
NameError: name 'app' is not defined
ERROR:nicegui:name 'app' is not defined
  + Exception Group Traceback (most recent call last):
  |   File "C:\Users\Keila\AppData\Local\Programs\Python\Python311\Lib\site-packages\starlette\_utils.py", line 76, in collapse_excgroups
  |     yield
  |   File "C:\Users\Keila\AppData\Local\Programs\Python\Python311\Lib\site-packages\starlette\middleware\base.py", line 178, in __call__
  |     async with anyio.create_task_group() as task_group:
  |   File "C:\Users\Keila\AppData\Local\Programs\Python\Python311\Lib\site-packages\anyio\_backends\_asyncio.py", line 767, in __aexit__
  |     raise BaseExceptionGroup(
  | ExceptionGroup: unhandled errors in a TaskGroup (1 sub-exception)
  +-+---------------- 1 ----------------
    | Traceback (most recent call last):
    |   File "C:\Users\Keila\AppData\Local\Programs\Python\Python311\Lib\site-packages\starlette\middleware\errors.py", line 165, in __call__
    |     await self.app(scope, receive, _send)
    |   File "C:\Users\Keila\AppData\Local\Programs\Python\Python311\Lib\site-packages\starlette\middleware\base.py", line 177, in __call__
    |     with recv_stream, send_stream, collapse_excgroups():
    |   File "C:\Users\Keila\AppData\Local\Programs\Python\Python311\Lib\contextlib.py", line 155, in __exit__
    |     self.gen.throw(typ, value, traceback)
    |   File "C:\Users\Keila\AppData\Local\Programs\Python\Python311\Lib\site-packages\starlette\_utils.py", line 82, in collapse_excgroups
    |     raise exc
    |   File "C:\Users\Keila\AppData\Local\Programs\Python\Python311\Lib\site-packages\starlette\middleware\base.py", line 179, in __call__
    |     response = await self.dispatch_func(request, call_next)
    |                ^^^^^^^^^^^^^^^^^^^^^^^^^^^^^^^^^^^^^^^^^^^^
    |   File "C:\Users\Keila\AppData\Local\Programs\Python\Python311\Lib\site-packages\nicegui\middlewares.py", line 23, in dispatch
    |     response = await call_next(request)
    |                ^^^^^^^^^^^^^^^^^^^^^^^^
    |   File "C:\Users\Keila\AppData\Local\Programs\Python\Python311\Lib\site-packages\starlette\middleware\base.py", line 154, in call_next
    |     raise app_exc
    |   File "C:\Users\Keila\AppData\Local\Programs\Python\Python311\Lib\site-packages\starlette\middleware\base.py", line 141, in coro
    |     await self.app(scope, receive_or_disconnect, send_no_error)
    |   File "C:\Users\Keila\AppData\Local\Programs\Python\Python311\Lib\site-packages\starlette\middleware\base.py", line 177, in __call__
    |     with recv_stream, send_stream, collapse_excgroups():
    |   File "C:\Users\Keila\AppData\Local\Programs\Python\Python311\Lib\contextlib.py", line 155, in __exit__
    |     self.gen.throw(typ, value, traceback)
    |   File "C:\Users\Keila\AppData\Local\Programs\Python\Python311\Lib\site-packages\starlette\_utils.py", line 82, in collapse_excgroups
    |     raise exc
    |   File "C:\Users\Keila\AppData\Local\Programs\Python\Python311\Lib\site-packages\starlette\middleware\base.py", line 179, in __call__
    |     response = await self.dispatch_func(request, call_next)
    |                ^^^^^^^^^^^^^^^^^^^^^^^^^^^^^^^^^^^^^^^^^^^^
    |   File "C:\Users\Keila\AppData\Local\Programs\Python\Python311\Lib\site-packages\nicegui\middlewares.py", line 13, in dispatch
    |     response = await call_next(request)
    |                ^^^^^^^^^^^^^^^^^^^^^^^^
    |   File "C:\Users\Keila\AppData\Local\Programs\Python\Python311\Lib\site-packages\starlette\middleware\base.py", line 154, in call_next
    |     raise app_exc
    |   File "C:\Users\Keila\AppData\Local\Programs\Python\Python311\Lib\site-packages\starlette\middleware\base.py", line 141, in coro
    |     await self.app(scope, receive_or_disconnect, send_no_error)
    |   File "C:\Users\Keila\AppData\Local\Programs\Python\Python311\Lib\site-packages\starlette\middleware\gzip.py", line 20, in __call__
    |     await responder(scope, receive, send)
    |   File "C:\Users\Keila\AppData\Local\Programs\Python\Python311\Lib\site-packages\starlette\middleware\gzip.py", line 39, in __call__
    |     await self.app(scope, receive, self.send_with_gzip)
    |   File "C:\Users\Keila\AppData\Local\Programs\Python\Python311\Lib\site-packages\starlette\middleware\exceptions.py", line 62, in __call__
    |     await wrap_app_handling_exceptions(self.app, conn)(scope, receive, send)
    |   File "C:\Users\Keila\AppData\Local\Programs\Python\Python311\Lib\site-packages\starlette\_exception_handler.py", line 53, in wrapped_app
    |     raise exc
    |   File "C:\Users\Keila\AppData\Local\Programs\Python\Python311\Lib\site-packages\starlette\_exception_handler.py", line 42, in wrapped_app
    |     await app(scope, receive, sender)
    |   File "C:\Users\Keila\AppData\Local\Programs\Python\Python311\Lib\site-packages\starlette\routing.py", line 715, in __call__
    |     await self.middleware_stack(scope, receive, send)
    |   File "C:\Users\Keila\AppData\Local\Programs\Python\Python311\Lib\site-packages\starlette\routing.py", line 735, in app
    |     await route.handle(scope, receive, send)
    |   File "C:\Users\Keila\AppData\Local\Programs\Python\Python311\Lib\site-packages\starlette\routing.py", line 288, in handle
    |     await self.app(scope, receive, send)
    |   File "C:\Users\Keila\AppData\Local\Programs\Python\Python311\Lib\site-packages\starlette\routing.py", line 76, in app
    |     await wrap_app_handling_exceptions(app, request)(scope, receive, send)
    |   File "C:\Users\Keila\AppData\Local\Programs\Python\Python311\Lib\site-packages\starlette\_exception_handler.py", line 53, in wrapped_app
    |     raise exc
    |   File "C:\Users\Keila\AppData\Local\Programs\Python\Python311\Lib\site-packages\starlette\_exception_handler.py", line 42, in wrapped_app
    |     await app(scope, receive, sender)
    |   File "C:\Users\Keila\AppData\Local\Programs\Python\Python311\Lib\site-packages\starlette\routing.py", line 73, in app
    |     response = await f(request)
    |                ^^^^^^^^^^^^^^^^
    |   File "C:\Users\Keila\AppData\Local\Programs\Python\Python311\Lib\site-packages\fastapi\routing.py", line 301, in app
    |     raw_response = await run_endpoint_function(
    |                    ^^^^^^^^^^^^^^^^^^^^^^^^^^^^
    |   File "C:\Users\Keila\AppData\Local\Programs\Python\Python311\Lib\site-packages\fastapi\routing.py", line 212, in run_endpoint_function
    |     return await dependant.call(**values)
    |            ^^^^^^^^^^^^^^^^^^^^^^^^^^^^^^
    |   File "C:\Users\Keila\AppData\Local\Programs\Python\Python311\Lib\site-packages\nicegui\page.py", line 153, in decorated
    |     return create_error_page(e, request)
    |            ^^^^^^^^^^^^^^^^^^^^^^^^^^^^^
    |   File "C:\Users\Keila\AppData\Local\Programs\Python\Python311\Lib\site-packages\nicegui\page.py", line 116, in create_error_page
    |     raise e
    |   File "C:\Users\Keila\AppData\Local\Programs\Python\Python311\Lib\site-packages\nicegui\page.py", line 147, in decorated
    |     result = func(*dec_args, **dec_kwargs)
    |              ^^^^^^^^^^^^^^^^^^^^^^^^^^^^^
    |   File "c:\Users\Keila\Downloads\VehicleMax-main (1)\VehicleMax-main\VIN_Decoder\VIN-Decoder.py", line 29, in vin_decoder_page
    |     for url in app.urls:
    |                ^^^
    | NameError: name 'app' is not defined
    +------------------------------------

During handling of the above exception, another exception occurred:

Traceback (most recent call last):
  File "C:\Users\Keila\AppData\Local\Programs\Python\Python311\Lib\site-packages\starlette\middleware\errors.py", line 165, in __call__
    await self.app(scope, receive, _send)
  File "C:\Users\Keila\AppData\Local\Programs\Python\Python311\Lib\site-packages\starlette\middleware\base.py", line 177, in __call__
    with recv_stream, send_stream, collapse_excgroups():
  File "C:\Users\Keila\AppData\Local\Programs\Python\Python311\Lib\contextlib.py", line 155, in __exit__
    self.gen.throw(typ, value, traceback)
  File "C:\Users\Keila\AppData\Local\Programs\Python\Python311\Lib\site-packages\starlette\_utils.py", line 82, in collapse_excgroups
    raise exc
  File "C:\Users\Keila\AppData\Local\Programs\Python\Python311\Lib\site-packages\starlette\middleware\base.py", line 179, in __call__
    response = await self.dispatch_func(request, call_next)
               ^^^^^^^^^^^^^^^^^^^^^^^^^^^^^^^^^^^^^^^^^^^^
  File "C:\Users\Keila\AppData\Local\Programs\Python\Python311\Lib\site-packages\nicegui\middlewares.py", line 23, in dispatch
    response = await call_next(request)
               ^^^^^^^^^^^^^^^^^^^^^^^^
  File "C:\Users\Keila\AppData\Local\Programs\Python\Python311\Lib\site-packages\starlette\middleware\base.py", line 154, in call_next
    raise app_exc
  File "C:\Users\Keila\AppData\Local\Programs\Python\Python311\Lib\site-packages\starlette\middleware\base.py", line 141, in coro
    await self.app(scope, receive_or_disconnect, send_no_error)
  File "C:\Users\Keila\AppData\Local\Programs\Python\Python311\Lib\site-packages\starlette\middleware\base.py", line 177, in __call__
    with recv_stream, send_stream, collapse_excgroups():
  File "C:\Users\Keila\AppData\Local\Programs\Python\Python311\Lib\contextlib.py", line 155, in __exit__
    self.gen.throw(typ, value, traceback)
  File "C:\Users\Keila\AppData\Local\Programs\Python\Python311\Lib\site-packages\starlette\_utils.py", line 82, in collapse_excgroups
    raise exc
  File "C:\Users\Keila\AppData\Local\Programs\Python\Python311\Lib\site-packages\starlette\middleware\base.py", line 179, in __call__
    response = await self.dispatch_func(request, call_next)
               ^^^^^^^^^^^^^^^^^^^^^^^^^^^^^^^^^^^^^^^^^^^^
  File "C:\Users\Keila\AppData\Local\Programs\Python\Python311\Lib\site-packages\nicegui\middlewares.py", line 13, in dispatch
    response = await call_next(request)
               ^^^^^^^^^^^^^^^^^^^^^^^^
  File "C:\Users\Keila\AppData\Local\Programs\Python\Python311\Lib\site-packages\starlette\middleware\base.py", line 154, in call_next
    raise app_exc
  File "C:\Users\Keila\AppData\Local\Programs\Python\Python311\Lib\site-packages\starlette\middleware\base.py", line 141, in coro
    await self.app(scope, receive_or_disconnect, send_no_error)
  File "C:\Users\Keila\AppData\Local\Programs\Python\Python311\Lib\site-packages\starlette\middleware\gzip.py", line 20, in __call__
    await responder(scope, receive, send)
  File "C:\Users\Keila\AppData\Local\Programs\Python\Python311\Lib\site-packages\starlette\middleware\gzip.py", line 39, in __call__
    await self.app(scope, receive, self.send_with_gzip)
  File "C:\Users\Keila\AppData\Local\Programs\Python\Python311\Lib\site-packages\starlette\middleware\exceptions.py", line 62, in __call__
    await wrap_app_handling_exceptions(self.app, conn)(scope, receive, send)
  File "C:\Users\Keila\AppData\Local\Programs\Python\Python311\Lib\site-packages\starlette\_exception_handler.py", line 53, in wrapped_app
    raise exc
  File "C:\Users\Keila\AppData\Local\Programs\Python\Python311\Lib\site-packages\starlette\_exception_handler.py", line 42, in wrapped_app
    await app(scope, receive, sender)
  File "C:\Users\Keila\AppData\Local\Programs\Python\Python311\Lib\site-packages\starlette\routing.py", line 715, in __call__
    await self.middleware_stack(scope, receive, send)
  File "C:\Users\Keila\AppData\Local\Programs\Python\Python311\Lib\site-packages\starlette\routing.py", line 735, in app
    await route.handle(scope, receive, send)
  File "C:\Users\Keila\AppData\Local\Programs\Python\Python311\Lib\site-packages\starlette\routing.py", line 288, in handle
    await self.app(scope, receive, send)
  File "C:\Users\Keila\AppData\Local\Programs\Python\Python311\Lib\site-packages\starlette\routing.py", line 76, in app
    await wrap_app_handling_exceptions(app, request)(scope, receive, send)
  File "C:\Users\Keila\AppData\Local\Programs\Python\Python311\Lib\site-packages\starlette\_exception_handler.py", line 53, in wrapped_app
    raise exc
  File "C:\Users\Keila\AppData\Local\Programs\Python\Python311\Lib\site-packages\starlette\_exception_handler.py", line 42, in wrapped_app
    await app(scope, receive, sender)
  File "C:\Users\Keila\AppData\Local\Programs\Python\Python311\Lib\site-packages\starlette\routing.py", line 73, in app
    response = await f(request)
               ^^^^^^^^^^^^^^^^
  File "C:\Users\Keila\AppData\Local\Programs\Python\Python311\Lib\site-packages\fastapi\routing.py", line 301, in app
    raw_response = await run_endpoint_function(
                   ^^^^^^^^^^^^^^^^^^^^^^^^^^^^
  File "C:\Users\Keila\AppData\Local\Programs\Python\Python311\Lib\site-packages\fastapi\routing.py", line 212, in run_endpoint_function
    return await dependant.call(**values)
           ^^^^^^^^^^^^^^^^^^^^^^^^^^^^^^
  File "C:\Users\Keila\AppData\Local\Programs\Python\Python311\Lib\site-packages\nicegui\page.py", line 153, in decorated
    return create_error_page(e, request)
           ^^^^^^^^^^^^^^^^^^^^^^^^^^^^^
  File "C:\Users\Keila\AppData\Local\Programs\Python\Python311\Lib\site-packages\nicegui\page.py", line 116, in create_error_page
    raise e
  File "C:\Users\Keila\AppData\Local\Programs\Python\Python311\Lib\site-packages\nicegui\page.py", line 147, in decorated
    result = func(*dec_args, **dec_kwargs)
             ^^^^^^^^^^^^^^^^^^^^^^^^^^^^^
  File "c:\Users\Keila\Downloads\VehicleMax-main (1)\VehicleMax-main\VIN_Decoder\VIN-Decoder.py", line 29, in vin_decoder_page
    for url in app.urls:
               ^^^
NameError: name 'app' is not defined
ERROR:nicegui:name 'app' is not defined
  + Exception Group Traceback (most recent call last):
  |   File "C:\Users\Keila\AppData\Local\Programs\Python\Python311\Lib\site-packages\starlette\_utils.py", line 76, in collapse_excgroups
  |     yield
  |   File "C:\Users\Keila\AppData\Local\Programs\Python\Python311\Lib\site-packages\starlette\middleware\base.py", line 178, in __call__
  |     async with anyio.create_task_group() as task_group:
  |   File "C:\Users\Keila\AppData\Local\Programs\Python\Python311\Lib\site-packages\anyio\_backends\_asyncio.py", line 767, in __aexit__
  |     raise BaseExceptionGroup(
  | ExceptionGroup: unhandled errors in a TaskGroup (1 sub-exception)
  +-+---------------- 1 ----------------
    | Traceback (most recent call last):
    |   File "C:\Users\Keila\AppData\Local\Programs\Python\Python311\Lib\site-packages\starlette\middleware\errors.py", line 165, in __call__
    |     await self.app(scope, receive, _send)
    |   File "C:\Users\Keila\AppData\Local\Programs\Python\Python311\Lib\site-packages\starlette\middleware\base.py", line 177, in __call__
    |     with recv_stream, send_stream, collapse_excgroups():
    |   File "C:\Users\Keila\AppData\Local\Programs\Python\Python311\Lib\contextlib.py", line 155, in __exit__
    |     self.gen.throw(typ, value, traceback)
    |   File "C:\Users\Keila\AppData\Local\Programs\Python\Python311\Lib\site-packages\starlette\_utils.py", line 82, in collapse_excgroups
    |     raise exc
    |   File "C:\Users\Keila\AppData\Local\Programs\Python\Python311\Lib\site-packages\starlette\middleware\base.py", line 179, in __call__
    |     response = await self.dispatch_func(request, call_next)
    |                ^^^^^^^^^^^^^^^^^^^^^^^^^^^^^^^^^^^^^^^^^^^^
    |   File "C:\Users\Keila\AppData\Local\Programs\Python\Python311\Lib\site-packages\nicegui\middlewares.py", line 23, in dispatch
    |     response = await call_next(request)
    |                ^^^^^^^^^^^^^^^^^^^^^^^^
    |   File "C:\Users\Keila\AppData\Local\Programs\Python\Python311\Lib\site-packages\starlette\middleware\base.py", line 154, in call_next
    |     raise app_exc
    |   File "C:\Users\Keila\AppData\Local\Programs\Python\Python311\Lib\site-packages\starlette\middleware\base.py", line 141, in coro
    |     await self.app(scope, receive_or_disconnect, send_no_error)
    |   File "C:\Users\Keila\AppData\Local\Programs\Python\Python311\Lib\site-packages\starlette\middleware\base.py", line 177, in __call__
    |     with recv_stream, send_stream, collapse_excgroups():
    |   File "C:\Users\Keila\AppData\Local\Programs\Python\Python311\Lib\contextlib.py", line 155, in __exit__
    |     self.gen.throw(typ, value, traceback)
    |   File "C:\Users\Keila\AppData\Local\Programs\Python\Python311\Lib\site-packages\starlette\_utils.py", line 82, in collapse_excgroups
    |     raise exc
    |   File "C:\Users\Keila\AppData\Local\Programs\Python\Python311\Lib\site-packages\starlette\middleware\base.py", line 179, in __call__
    |     response = await self.dispatch_func(request, call_next)
    |                ^^^^^^^^^^^^^^^^^^^^^^^^^^^^^^^^^^^^^^^^^^^^
    |   File "C:\Users\Keila\AppData\Local\Programs\Python\Python311\Lib\site-packages\nicegui\middlewares.py", line 13, in dispatch
    |     response = await call_next(request)
    |                ^^^^^^^^^^^^^^^^^^^^^^^^
    |   File "C:\Users\Keila\AppData\Local\Programs\Python\Python311\Lib\site-packages\starlette\middleware\base.py", line 154, in call_next
    |     raise app_exc
    |   File "C:\Users\Keila\AppData\Local\Programs\Python\Python311\Lib\site-packages\starlette\middleware\base.py", line 141, in coro
    |     await self.app(scope, receive_or_disconnect, send_no_error)
    |   File "C:\Users\Keila\AppData\Local\Programs\Python\Python311\Lib\site-packages\starlette\middleware\gzip.py", line 20, in __call__
    |     await responder(scope, receive, send)
    |   File "C:\Users\Keila\AppData\Local\Programs\Python\Python311\Lib\site-packages\starlette\middleware\gzip.py", line 39, in __call__
    |     await self.app(scope, receive, self.send_with_gzip)
    |   File "C:\Users\Keila\AppData\Local\Programs\Python\Python311\Lib\site-packages\starlette\middleware\exceptions.py", line 62, in __call__
    |     await wrap_app_handling_exceptions(self.app, conn)(scope, receive, send)
    |   File "C:\Users\Keila\AppData\Local\Programs\Python\Python311\Lib\site-packages\starlette\_exception_handler.py", line 53, in wrapped_app
    |     raise exc
    |   File "C:\Users\Keila\AppData\Local\Programs\Python\Python311\Lib\site-packages\starlette\_exception_handler.py", line 42, in wrapped_app
    |     await app(scope, receive, sender)
    |   File "C:\Users\Keila\AppData\Local\Programs\Python\Python311\Lib\site-packages\starlette\routing.py", line 715, in __call__
    |     await self.middleware_stack(scope, receive, send)
    |   File "C:\Users\Keila\AppData\Local\Programs\Python\Python311\Lib\site-packages\starlette\routing.py", line 735, in app
    |     await route.handle(scope, receive, send)
    |   File "C:\Users\Keila\AppData\Local\Programs\Python\Python311\Lib\site-packages\starlette\routing.py", line 288, in handle
    |     await self.app(scope, receive, send)
    |   File "C:\Users\Keila\AppData\Local\Programs\Python\Python311\Lib\site-packages\starlette\routing.py", line 76, in app
    |     await wrap_app_handling_exceptions(app, request)(scope, receive, send)
    |   File "C:\Users\Keila\AppData\Local\Programs\Python\Python311\Lib\site-packages\starlette\_exception_handler.py", line 53, in wrapped_app
    |     raise exc
    |   File "C:\Users\Keila\AppData\Local\Programs\Python\Python311\Lib\site-packages\starlette\_exception_handler.py", line 42, in wrapped_app
    |     await app(scope, receive, sender)
    |   File "C:\Users\Keila\AppData\Local\Programs\Python\Python311\Lib\site-packages\starlette\routing.py", line 73, in app
    |     response = await f(request)
    |                ^^^^^^^^^^^^^^^^
    |   File "C:\Users\Keila\AppData\Local\Programs\Python\Python311\Lib\site-packages\fastapi\routing.py", line 301, in app
    |     raw_response = await run_endpoint_function(
    |                    ^^^^^^^^^^^^^^^^^^^^^^^^^^^^
    |   File "C:\Users\Keila\AppData\Local\Programs\Python\Python311\Lib\site-packages\fastapi\routing.py", line 212, in run_endpoint_function
    |     return await dependant.call(**values)
    |            ^^^^^^^^^^^^^^^^^^^^^^^^^^^^^^
    |   File "C:\Users\Keila\AppData\Local\Programs\Python\Python311\Lib\site-packages\nicegui\page.py", line 153, in decorated
    |     return create_error_page(e, request)
    |            ^^^^^^^^^^^^^^^^^^^^^^^^^^^^^
    |   File "C:\Users\Keila\AppData\Local\Programs\Python\Python311\Lib\site-packages\nicegui\page.py", line 116, in create_error_page
    |     raise e
    |   File "C:\Users\Keila\AppData\Local\Programs\Python\Python311\Lib\site-packages\nicegui\page.py", line 147, in decorated
    |     result = func(*dec_args, **dec_kwargs)
    |              ^^^^^^^^^^^^^^^^^^^^^^^^^^^^^
    |   File "c:\Users\Keila\Downloads\VehicleMax-main (1)\VehicleMax-main\VIN_Decoder\VIN-Decoder.py", line 29, in index
    |     for url in app.urls:
    |                ^^^
    | NameError: name 'app' is not defined
    +------------------------------------

During handling of the above exception, another exception occurred:

Traceback (most recent call last):
  File "C:\Users\Keila\AppData\Local\Programs\Python\Python311\Lib\site-packages\starlette\middleware\errors.py", line 165, in __call__
    await self.app(scope, receive, _send)
  File "C:\Users\Keila\AppData\Local\Programs\Python\Python311\Lib\site-packages\starlette\middleware\base.py", line 177, in __call__
    with recv_stream, send_stream, collapse_excgroups():
  File "C:\Users\Keila\AppData\Local\Programs\Python\Python311\Lib\contextlib.py", line 155, in __exit__
    self.gen.throw(typ, value, traceback)
  File "C:\Users\Keila\AppData\Local\Programs\Python\Python311\Lib\site-packages\starlette\_utils.py", line 82, in collapse_excgroups
    raise exc
  File "C:\Users\Keila\AppData\Local\Programs\Python\Python311\Lib\site-packages\starlette\middleware\base.py", line 179, in __call__
    response = await self.dispatch_func(request, call_next)
               ^^^^^^^^^^^^^^^^^^^^^^^^^^^^^^^^^^^^^^^^^^^^
  File "C:\Users\Keila\AppData\Local\Programs\Python\Python311\Lib\site-packages\nicegui\middlewares.py", line 23, in dispatch
    response = await call_next(request)
               ^^^^^^^^^^^^^^^^^^^^^^^^
  File "C:\Users\Keila\AppData\Local\Programs\Python\Python311\Lib\site-packages\starlette\middleware\base.py", line 154, in call_next
    raise app_exc
  File "C:\Users\Keila\AppData\Local\Programs\Python\Python311\Lib\site-packages\starlette\middleware\base.py", line 141, in coro
    await self.app(scope, receive_or_disconnect, send_no_error)
  File "C:\Users\Keila\AppData\Local\Programs\Python\Python311\Lib\site-packages\starlette\middleware\base.py", line 177, in __call__
    with recv_stream, send_stream, collapse_excgroups():
  File "C:\Users\Keila\AppData\Local\Programs\Python\Python311\Lib\contextlib.py", line 155, in __exit__
    self.gen.throw(typ, value, traceback)
  File "C:\Users\Keila\AppData\Local\Programs\Python\Python311\Lib\site-packages\starlette\_utils.py", line 82, in collapse_excgroups
    raise exc
  File "C:\Users\Keila\AppData\Local\Programs\Python\Python311\Lib\site-packages\starlette\middleware\base.py", line 179, in __call__
    response = await self.dispatch_func(request, call_next)
               ^^^^^^^^^^^^^^^^^^^^^^^^^^^^^^^^^^^^^^^^^^^^
  File "C:\Users\Keila\AppData\Local\Programs\Python\Python311\Lib\site-packages\nicegui\middlewares.py", line 13, in dispatch
    response = await call_next(request)
               ^^^^^^^^^^^^^^^^^^^^^^^^
  File "C:\Users\Keila\AppData\Local\Programs\Python\Python311\Lib\site-packages\starlette\middleware\base.py", line 154, in call_next
    raise app_exc
  File "C:\Users\Keila\AppData\Local\Programs\Python\Python311\Lib\site-packages\starlette\middleware\base.py", line 141, in coro
    await self.app(scope, receive_or_disconnect, send_no_error)
  File "C:\Users\Keila\AppData\Local\Programs\Python\Python311\Lib\site-packages\starlette\middleware\gzip.py", line 20, in __call__
    await responder(scope, receive, send)
  File "C:\Users\Keila\AppData\Local\Programs\Python\Python311\Lib\site-packages\starlette\middleware\gzip.py", line 39, in __call__
    await self.app(scope, receive, self.send_with_gzip)
  File "C:\Users\Keila\AppData\Local\Programs\Python\Python311\Lib\site-packages\starlette\middleware\exceptions.py", line 62, in __call__
    await wrap_app_handling_exceptions(self.app, conn)(scope, receive, send)
  File "C:\Users\Keila\AppData\Local\Programs\Python\Python311\Lib\site-packages\starlette\_exception_handler.py", line 53, in wrapped_app
    raise exc
  File "C:\Users\Keila\AppData\Local\Programs\Python\Python311\Lib\site-packages\starlette\_exception_handler.py", line 42, in wrapped_app
    await app(scope, receive, sender)
  File "C:\Users\Keila\AppData\Local\Programs\Python\Python311\Lib\site-packages\starlette\routing.py", line 715, in __call__
    await self.middleware_stack(scope, receive, send)
  File "C:\Users\Keila\AppData\Local\Programs\Python\Python311\Lib\site-packages\starlette\routing.py", line 735, in app
    await route.handle(scope, receive, send)
  File "C:\Users\Keila\AppData\Local\Programs\Python\Python311\Lib\site-packages\starlette\routing.py", line 288, in handle
    await self.app(scope, receive, send)
  File "C:\Users\Keila\AppData\Local\Programs\Python\Python311\Lib\site-packages\starlette\routing.py", line 76, in app
    await wrap_app_handling_exceptions(app, request)(scope, receive, send)
  File "C:\Users\Keila\AppData\Local\Programs\Python\Python311\Lib\site-packages\starlette\_exception_handler.py", line 53, in wrapped_app
    raise exc
  File "C:\Users\Keila\AppData\Local\Programs\Python\Python311\Lib\site-packages\starlette\_exception_handler.py", line 42, in wrapped_app
    await app(scope, receive, sender)
  File "C:\Users\Keila\AppData\Local\Programs\Python\Python311\Lib\site-packages\starlette\routing.py", line 73, in app
    response = await f(request)
               ^^^^^^^^^^^^^^^^
  File "C:\Users\Keila\AppData\Local\Programs\Python\Python311\Lib\site-packages\fastapi\routing.py", line 301, in app
    raw_response = await run_endpoint_function(
                   ^^^^^^^^^^^^^^^^^^^^^^^^^^^^
  File "C:\Users\Keila\AppData\Local\Programs\Python\Python311\Lib\site-packages\fastapi\routing.py", line 212, in run_endpoint_function
    return await dependant.call(**values)
           ^^^^^^^^^^^^^^^^^^^^^^^^^^^^^^
  File "C:\Users\Keila\AppData\Local\Programs\Python\Python311\Lib\site-packages\nicegui\page.py", line 153, in decorated
    return create_error_page(e, request)
           ^^^^^^^^^^^^^^^^^^^^^^^^^^^^^
  File "C:\Users\Keila\AppData\Local\Programs\Python\Python311\Lib\site-packages\nicegui\page.py", line 116, in create_error_page
    raise e
  File "C:\Users\Keila\AppData\Local\Programs\Python\Python311\Lib\site-packages\nicegui\page.py", line 147, in decorated
    result = func(*dec_args, **dec_kwargs)
             ^^^^^^^^^^^^^^^^^^^^^^^^^^^^^
  File "c:\Users\Keila\Downloads\VehicleMax-main (1)\VehicleMax-main\VIN_Decoder\VIN-Decoder.py", line 29, in index
    for url in app.urls:
               ^^^
NameError: name 'app' is not defined
ERROR:root:VIN lookup exception: Link.__init__() got an unexpected keyword argument 'on_click'
ERROR:root:Cars API exception: Link.__init__() got an unexpected keyword argument 'on_click'
